Workbook

Sheet Purchase Orders
A1: DC_CODE | B1: PURCH_ORDER_NUMBER | C1: PURCH_ORDER_DATE | D1: EXPECTED_DATE | E1: SUPPLIER_CODE | F1: SUPPLIER NAME | G1: PURCH_ORDER_LINE | H1: EAN_NO | I1: PRODUCT_CODE | J1: PRODUCT_DESCRIPTION | K1: VENDOR_ITEM_CODE | L1: ORDERING_UNIT | M1: QTY_PER_PACK_OF_ORDERING_UOM | N1: NO_OF_PACKS_ORDERED | O1: TOTAL_QUANTITY | P1: CLOSING_STOCK | Q1: MRP_PER_UNIT | R1: LANDING_COST_INCL_TAX_PER_UNIT | S1: SALES_TAX | T1: COST_PRICE_INCL_TAX_PER_PO_OU | U1: TAX_PER | V1: CURRENCY | W1: HSN | X1: MASTER PRODUCT CODE | Y1: Order type | Z1: S | AA1: M | AB1: L | AC1: XL | AD1: XXL | AE1: SKU | AF1: Colour | AG1: location | AH1: RP DESCRPTION
A2: SZAF | B2: 5115513594 | C2: 04.08.2026 | D2: 15.10.2026 | E2: 10337044 | F2: UNITED TEXTILE MILLS PRIVATE LIMITE | G2: 1 | H2: 8909490275917 | I2: 441814970001 | J2: KRTS-APWN26-GETKRTSFUT645, LIME GREEN, S | L2: EA | M2: 1 | N2: 64 | O2: 64 | Q2: 276.7 | R2: 276.7 | S2: 885.44 | T2: 17708.8 | U2: 5 | V2: INR | X2: =IF(ISNUMBER(VALUE(LEFT(J2,1))),LEFT(J2,MIN(IFERROR(FIND("A",UPPER(J2)),LEN(J2)+1),IFERROR(FIND("B",UPPER(J2)),LEN(J2)+1),IFERROR(FIND("C",UPPER(J2)),LEN(J2)+1),IFERROR(FIND("D",UPPER(J2)),LEN(J2)+1),IFERROR(FIND("E",UPPER(J2)),LEN(J2)+1),IFERROR(FIND("F",UPPER(J2)),LEN(J2)+1),IFERROR(FIND("G",UPPER(J2)),LEN(J2)+1),IFERROR(FIND("H",UPPER(J2)),LEN(J2)+1),IFERROR(FIND("I",UPPER(J2)),LEN(J2)+1),IFERROR(FIND("J",UPPER(J2)),LEN(J2)+1),IFERROR(FIND("K",UPPER(J2)),LEN(J2)+1),IFERROR(FIND("L",UPPER(J2)),LEN(J2)+1),IFERROR(FIND("M",UPPER(J2)),LEN(J2)+1),IFERROR(FIND("N",UPPER(J2)),LEN(J2)+1),IFERROR(FIND("O",UPPER(J2)),LEN(J2)+1),IFERROR(FIND("P",UPPER(J2)),LEN(J2)+1),IFERROR(FIND("Q",UPPER(J2)),LEN(J2)+1),IFERROR(FIND("R",UPPER(J2)),LEN(J2)+1),IFERROR(FIND("S",UPPER(J2)),LEN(J2)+1),IFERROR(FIND("T",UPPER(J2)),LEN(J2)+1),IFERROR(FIND("U",UPPER(J2)),LEN(J2)+1),IFERROR(FIND("V",UPPER(J2)),LEN(J2)+1),IFERROR(FIND("W",UPPER(J2)),LEN(J2)+1),IFERROR(FIND("X",UPPER(J2)),LEN(J2)+1),IFERROR(FIND("Y",UPPER(J2)),LEN(J2)+1),IFERROR(FIND("Z",UPPER(J2)),LEN(J2)+1))-1),LEFT(TEXT(I2,"0"),LEN(TEXT(I2,"0"))-3)) -> 441814970 | Y2: =IF(ISNUMBER(SEARCH("(RP)",J2)),"RP","DC") -> DC | Z2: =IF(ISNUMBER(SEARCH("(RP)",J2)),O2,IF(RIGHT(TRIM(J2),3)=", S",O2,0)) -> 64 | AA2: =IF(ISNUMBER(SEARCH("(RP)",J2)),O2,IF(RIGHT(TRIM(J2),3)=", M",O2,0)) -> 0 | AB2: =IF(ISNUMBER(SEARCH("(RP)",J2)),O2,IF(RIGHT(TRIM(J2),3)=", L",O2,0)) -> 0 | AC2: =IF(ISNUMBER(SEARCH("(RP)",J2)),O2,IF(RIGHT(TRIM(J2),4)=", XL",O2,0)) -> 0 | AD2: =IF(ISNUMBER(SEARCH("(RP)",J2)),O2,IF(OR(RIGHT(TRIM(J2),5)=", XXL",RIGHT(TRIM(J2),5)=", 2XL"),O2,0)) -> 0 | AE2: {=IFERROR(_xlfn.XLOOKUP(H2,Sheet1!$G:$G,Sheet1!$F:$F),IFERROR(_xlfn.XLOOKUP(1,(--($X$2:$X$1074=X2))*(--ISNUMBER(MATCH($H$2:$H$1074,Sheet1!$G:$G,0))),_xlfn.XLOOKUP($H$2:$H$1074,Sheet1!$G:$G,Sheet1!$F:$F,"")),"NOT FOUND"))} -> GETKRTSFUT6451 | AF2: =IFERROR(IF(ISNUMBER(SEARCH("(RP)",J2)),TRIM(SUBSTITUTE(MID(J2,10,LEN(J2)),"(RP)","")),TRIM(MID(J2,FIND(",",J2)+1,FIND(",",J2,FIND(",",J2)+1)-FIND(",",J2)-1))),"") -> LIME GREEN | AG2: =IF(A2="SZAF","Bangalore",IF(A2="SAEX","JHAJJAR",IF(A2="S0EU","HARIPAL",""))) -> Bangalore | AH2: {=IF(OR(J2="",AE2="",AE2="NOT FOUND"),"",IF(Y2="RP",_xlfn.LET(_xlpm.desc,_xlfn.XLOOKUP(1,(--(Sheet1!$F$2:$F$754=AE2))*(--ISNUMBER(FIND("-",Sheet1!$W$2:$W$754,FIND("-",Sheet1!$W$2:$W$754)+1))),Sheet1!$W$2:$W$754,""),IF(_xlpm.desc="","NOT FOUND",LEFT(_xlpm.desc,FIND("-",_xlpm.desc,FIND("-",_xlpm.desc)+1))&AE2)),LEFT(J2,FIND("-",J2,FIND("-",J2)+1))&AE2))} -> KRTS-APWN26-GETKRTSFUT6451
A3: SZAF | B3: 5115513594 | C3: 04.08.2026 | D3: 15.10.2026 | E3: 10337044 | F3: UNITED TEXTILE MILLS PRIVATE LIMITE | G3: 2 | H3: 8909490275924 | I3: 441814970002 | J3: KRTS-APWN26-GETKRTSFUT645, LIME GREEN, M | L3: EA | M3: 1 | N3: 273 | O3: 273 | Q3: 276.7 | R3: 276.7 | S3: 3776.96 | T3: 75539.1 | U3: 5 | V3: INR | X3: =IF(ISNUMBER(VALUE(LEFT(J3,1))),LEFT(J3,MIN(IFERROR(FIND("A",UPPER(J3)),LEN(J3)+1),IFERROR(FIND("B",UPPER(J3)),LEN(J3)+1),IFERROR(FIND("C",UPPER(J3)),LEN(J3)+1),IFERROR(FIND("D",UPPER(J3)),LEN(J3)+1),IFERROR(FIND("E",UPPER(J3)),LEN(J3)+1),IFERROR(FIND("F",UPPER(J3)),LEN(J3)+1),IFERROR(FIND("G",UPPER(J3)),LEN(J3)+1),IFERROR(FIND("H",UPPER(J3)),LEN(J3)+1),IFERROR(FIND("I",UPPER(J3)),LEN(J3)+1),IFERROR(FIND("J",UPPER(J3)),LEN(J3)+1),IFERROR(FIND("K",UPPER(J3)),LEN(J3)+1),IFERROR(FIND("L",UPPER(J3)),LEN(J3)+1),IFERROR(FIND("M",UPPER(J3)),LEN(J3)+1),IFERROR(FIND("N",UPPER(J3)),LEN(J3)+1),IFERROR(FIND("O",UPPER(J3)),LEN(J3)+1),IFERROR(FIND("P",UPPER(J3)),LEN(J3)+1),IFERROR(FIND("Q",UPPER(J3)),LEN(J3)+1),IFERROR(FIND("R",UPPER(J3)),LEN(J3)+1),IFERROR(FIND("S",UPPER(J3)),LEN(J3)+1),IFERROR(FIND("T",UPPER(J3)),LEN(J3)+1),IFERROR(FIND("U",UPPER(J3)),LEN(J3)+1),IFERROR(FIND("V",UPPER(J3)),LEN(J3)+1),IFERROR(FIND("W",UPPER(J3)),LEN(J3)+1),IFERROR(FIND("X",UPPER(J3)),LEN(J3)+1),IFERROR(FIND("Y",UPPER(J3)),LEN(J3)+1),IFERROR(FIND("Z",UPPER(J3)),LEN(J3)+1))-1),LEFT(TEXT(I3,"0"),LEN(TEXT(I3,"0"))-3)) -> 441814970 | Y3: =IF(ISNUMBER(SEARCH("(RP)",J3)),"RP","DC") -> DC | Z3: =IF(ISNUMBER(SEARCH("(RP)",J3)),O3,IF(RIGHT(TRIM(J3),3)=", S",O3,0)) -> 0 | AA3: =IF(ISNUMBER(SEARCH("(RP)",J3)),O3,IF(RIGHT(TRIM(J3),3)=", M",O3,0)) -> 273 | AB3: =IF(ISNUMBER(SEARCH("(RP)",J3)),O3,IF(RIGHT(TRIM(J3),3)=", L",O3,0)) -> 0 | AC3: =IF(ISNUMBER(SEARCH("(RP)",J3)),O3,IF(RIGHT(TRIM(J3),4)=", XL",O3,0)) -> 0 | AD3: =IF(ISNUMBER(SEARCH("(RP)",J3)),O3,IF(OR(RIGHT(TRIM(J3),5)=", XXL",RIGHT(TRIM(J3),5)=", 2XL"),O3,0)) -> 0 | AE3: {=IFERROR(_xlfn.XLOOKUP(H3,Sheet1!$G:$G,Sheet1!$F:$F),IFERROR(_xlfn.XLOOKUP(1,(--($X$2:$X$1074=X3))*(--ISNUMBER(MATCH($H$2:$H$1074,Sheet1!$G:$G,0))),_xlfn.XLOOKUP($H$2:$H$1074,Sheet1!$G:$G,Sheet1!$F:$F,"")),"NOT FOUND"))} -> GETKRTSFUT6451 | AF3: =IFERROR(IF(ISNUMBER(SEARCH("(RP)",J3)),TRIM(SUBSTITUTE(MID(J3,10,LEN(J3)),"(RP)","")),TRIM(MID(J3,FIND(",",J3)+1,FIND(",",J3,FIND(",",J3)+1)-FIND(",",J3)-1))),"") -> LIME GREEN | AG3: =IF(A3="SZAF","Bangalore",IF(A3="SAEX","JHAJJAR",IF(A3="S0EU","HARIPAL",""))) -> Bangalore | AH3: {=IF(OR(J3="",AE3="",AE3="NOT FOUND"),"",IF(Y3="RP",_xlfn.LET(_xlpm.desc,_xlfn.XLOOKUP(1,(--(Sheet1!$F$2:$F$754=AE3))*(--ISNUMBER(FIND("-",Sheet1!$W$2:$W$754,FIND("-",Sheet1!$W$2:$W$754)+1))),Sheet1!$W$2:$W$754,""),IF(_xlpm.desc="","NOT FOUND",LEFT(_xlpm.desc,FIND("-",_xlpm.desc,FIND("-",_xlpm.desc)+1))&AE3)),LEFT(J3,FIND("-",J3,FIND("-",J3)+1))&AE3))} -> KRTS-APWN26-GETKRTSFUT6451
A4: SZAF | B4: 5115513594 | C4: 04.08.2026 | D4: 15.10.2026 | E4: 10337044 | F4: UNITED TEXTILE MILLS PRIVATE LIMITE | G4: 3 | H4: 8909490275948 | I4: 441814970003 | J4: KRTS-APWN26-GETKRTSFUT645, LIME GREEN, L | L4: EA | M4: 1 | N4: 257 | O4: 257 | Q4: 276.7 | R4: 276.7 | S4: 3555.6 | T4: 71111.9 | U4: 5 | V4: INR | X4: =IF(ISNUMBER(VALUE(LEFT(J4,1))),LEFT(J4,MIN(IFERROR(FIND("A",UPPER(J4)),LEN(J4)+1),IFERROR(FIND("B",UPPER(J4)),LEN(J4)+1),IFERROR(FIND("C",UPPER(J4)),LEN(J4)+1),IFERROR(FIND("D",UPPER(J4)),LEN(J4)+1),IFERROR(FIND("E",UPPER(J4)),LEN(J4)+1),IFERROR(FIND("F",UPPER(J4)),LEN(J4)+1),IFERROR(FIND("G",UPPER(J4)),LEN(J4)+1),IFERROR(FIND("H",UPPER(J4)),LEN(J4)+1),IFERROR(FIND("I",UPPER(J4)),LEN(J4)+1),IFERROR(FIND("J",UPPER(J4)),LEN(J4)+1),IFERROR(FIND("K",UPPER(J4)),LEN(J4)+1),IFERROR(FIND("L",UPPER(J4)),LEN(J4)+1),IFERROR(FIND("M",UPPER(J4)),LEN(J4)+1),IFERROR(FIND("N",UPPER(J4)),LEN(J4)+1),IFERROR(FIND("O",UPPER(J4)),LEN(J4)+1),IFERROR(FIND("P",UPPER(J4)),LEN(J4)+1),IFERROR(FIND("Q",UPPER(J4)),LEN(J4)+1),IFERROR(FIND("R",UPPER(J4)),LEN(J4)+1),IFERROR(FIND("S",UPPER(J4)),LEN(J4)+1),IFERROR(FIND("T",UPPER(J4)),LEN(J4)+1),IFERROR(FIND("U",UPPER(J4)),LEN(J4)+1),IFERROR(FIND("V",UPPER(J4)),LEN(J4)+1),IFERROR(FIND("W",UPPER(J4)),LEN(J4)+1),IFERROR(FIND("X",UPPER(J4)),LEN(J4)+1),IFERROR(FIND("Y",UPPER(J4)),LEN(J4)+1),IFERROR(FIND("Z",UPPER(J4)),LEN(J4)+1))-1),LEFT(TEXT(I4,"0"),LEN(TEXT(I4,"0"))-3)) -> 441814970 | Y4: =IF(ISNUMBER(SEARCH("(RP)",J4)),"RP","DC") -> DC | Z4: =IF(ISNUMBER(SEARCH("(RP)",J4)),O4,IF(RIGHT(TRIM(J4),3)=", S",O4,0)) -> 0 | AA4: =IF(ISNUMBER(SEARCH("(RP)",J4)),O4,IF(RIGHT(TRIM(J4),3)=", M",O4,0)) -> 0 | AB4: =IF(ISNUMBER(SEARCH("(RP)",J4)),O4,IF(RIGHT(TRIM(J4),3)=", L",O4,0)) -> 257 | AC4: =IF(ISNUMBER(SEARCH("(RP)",J4)),O4,IF(RIGHT(TRIM(J4),4)=", XL",O4,0)) -> 0 | AD4: =IF(ISNUMBER(SEARCH("(RP)",J4)),O4,IF(OR(RIGHT(TRIM(J4),5)=", XXL",RIGHT(TRIM(J4),5)=", 2XL"),O4,0)) -> 0 | AE4: {=IFERROR(_xlfn.XLOOKUP(H4,Sheet1!$G:$G,Sheet1!$F:$F),IFERROR(_xlfn.XLOOKUP(1,(--($X$2:$X$1074=X4))*(--ISNUMBER(MATCH($H$2:$H$1074,Sheet1!$G:$G,0))),_xlfn.XLOOKUP($H$2:$H$1074,Sheet1!$G:$G,Sheet1!$F:$F,"")),"NOT FOUND"))} -> GETKRTSFUT6451 | AF4: =IFERROR(IF(ISNUMBER(SEARCH("(RP)",J4)),TRIM(SUBSTITUTE(MID(J4,10,LEN(J4)),"(RP)","")),TRIM(MID(J4,FIND(",",J4)+1,FIND(",",J4,FIND(",",J4)+1)-FIND(",",J4)-1))),"") -> LIME GREEN | AG4: =IF(A4="SZAF","Bangalore",IF(A4="SAEX","JHAJJAR",IF(A4="S0EU","HARIPAL",""))) -> Bangalore | AH4: {=IF(OR(J4="",AE4="",AE4="NOT FOUND"),"",IF(Y4="RP",_xlfn.LET(_xlpm.desc,_xlfn.XLOOKUP(1,(--(Sheet1!$F$2:$F$754=AE4))*(--ISNUMBER(FIND("-",Sheet1!$W$2:$W$754,FIND("-",Sheet1!$W$2:$W$754)+1))),Sheet1!$W$2:$W$754,""),IF(_xlpm.desc="","NOT FOUND",LEFT(_xlpm.desc,FIND("-",_xlpm.desc,FIND("-",_xlpm.desc)+1))&AE4)),LEFT(J4,FIND("-",J4,FIND("-",J4)+1))&AE4))} -> KRTS-APWN26-GETKRTSFUT6451
A5: SZAF | B5: 5115513594 | C5: 04.08.2026 | D5: 15.10.2026 | E5: 10337044 | F5: UNITED TEXTILE MILLS PRIVATE LIMITE | G5: 4 | H5: 8909490275955 | I5: 441814970004 | J5: KRTS-APWN26-GETKRTSFUT64, LIME GREEN, XL | L5: EA | M5: 1 | N5: 273 | O5: 273 | Q5: 276.7 | R5: 276.7 | S5: 3776.96 | T5: 75539.1 | U5: 5 | V5: INR | X5: =IF(ISNUMBER(VALUE(LEFT(J5,1))),LEFT(J5,MIN(IFERROR(FIND("A",UPPER(J5)),LEN(J5)+1),IFERROR(FIND("B",UPPER(J5)),LEN(J5)+1),IFERROR(FIND("C",UPPER(J5)),LEN(J5)+1),IFERROR(FIND("D",UPPER(J5)),LEN(J5)+1),IFERROR(FIND("E",UPPER(J5)),LEN(J5)+1),IFERROR(FIND("F",UPPER(J5)),LEN(J5)+1),IFERROR(FIND("G",UPPER(J5)),LEN(J5)+1),IFERROR(FIND("H",UPPER(J5)),LEN(J5)+1),IFERROR(FIND("I",UPPER(J5)),LEN(J5)+1),IFERROR(FIND("J",UPPER(J5)),LEN(J5)+1),IFERROR(FIND("K",UPPER(J5)),LEN(J5)+1),IFERROR(FIND("L",UPPER(J5)),LEN(J5)+1),IFERROR(FIND("M",UPPER(J5)),LEN(J5)+1),IFERROR(FIND("N",UPPER(J5)),LEN(J5)+1),IFERROR(FIND("O",UPPER(J5)),LEN(J5)+1),IFERROR(FIND("P",UPPER(J5)),LEN(J5)+1),IFERROR(FIND("Q",UPPER(J5)),LEN(J5)+1),IFERROR(FIND("R",UPPER(J5)),LEN(J5)+1),IFERROR(FIND("S",UPPER(J5)),LEN(J5)+1),IFERROR(FIND("T",UPPER(J5)),LEN(J5)+1),IFERROR(FIND("U",UPPER(J5)),LEN(J5)+1),IFERROR(FIND("V",UPPER(J5)),LEN(J5)+1),IFERROR(FIND("W",UPPER(J5)),LEN(J5)+1),IFERROR(FIND("X",UPPER(J5)),LEN(J5)+1),IFERROR(FIND("Y",UPPER(J5)),LEN(J5)+1),IFERROR(FIND("Z",UPPER(J5)),LEN(J5)+1))-1),LEFT(TEXT(I5,"0"),LEN(TEXT(I5,"0"))-3)) -> 441814970 | Y5: =IF(ISNUMBER(SEARCH("(RP)",J5)),"RP","DC") -> DC | Z5: =IF(ISNUMBER(SEARCH("(RP)",J5)),O5,IF(RIGHT(TRIM(J5),3)=", S",O5,0)) -> 0 | AA5: =IF(ISNUMBER(SEARCH("(RP)",J5)),O5,IF(RIGHT(TRIM(J5),3)=", M",O5,0)) -> 0 | AB5: =IF(ISNUMBER(SEARCH("(RP)",J5)),O5,IF(RIGHT(TRIM(J5),3)=", L",O5,0)) -> 0 | AC5: =IF(ISNUMBER(SEARCH("(RP)",J5)),O5,IF(RIGHT(TRIM(J5),4)=", XL",O5,0)) -> 273 | AD5: =IF(ISNUMBER(SEARCH("(RP)",J5)),O5,IF(OR(RIGHT(TRIM(J5),5)=", XXL",RIGHT(TRIM(J5),5)=", 2XL"),O5,0)) -> 0 | AE5: {=IFERROR(_xlfn.XLOOKUP(H5,Sheet1!$G:$G,Sheet1!$F:$F),IFERROR(_xlfn.XLOOKUP(1,(--($X$2:$X$1074=X5))*(--ISNUMBER(MATCH($H$2:$H$1074,Sheet1!$G:$G,0))),_xlfn.XLOOKUP($H$2:$H$1074,Sheet1!$G:$G,Sheet1!$F:$F,"")),"NOT FOUND"))} -> GETKRTSFUT6451 | AF5: =IFERROR(IF(ISNUMBER(SEARCH("(RP)",J5)),TRIM(SUBSTITUTE(MID(J5,10,LEN(J5)),"(RP)","")),TRIM(MID(J5,FIND(",",J5)+1,FIND(",",J5,FIND(",",J5)+1)-FIND(",",J5)-1))),"") -> LIME GREEN | AG5: =IF(A5="SZAF","Bangalore",IF(A5="SAEX","JHAJJAR",IF(A5="S0EU","HARIPAL",""))) -> Bangalore | AH5: {=IF(OR(J5="",AE5="",AE5="NOT FOUND"),"",IF(Y5="RP",_xlfn.LET(_xlpm.desc,_xlfn.XLOOKUP(1,(--(Sheet1!$F$2:$F$754=AE5))*(--ISNUMBER(FIND("-",Sheet1!$W$2:$W$754,FIND("-",Sheet1!$W$2:$W$754)+1))),Sheet1!$W$2:$W$754,""),IF(_xlpm.desc="","NOT FOUND",LEFT(_xlpm.desc,FIND("-",_xlpm.desc,FIND("-",_xlpm.desc)+1))&AE5)),LEFT(J5,FIND("-",J5,FIND("-",J5)+1))&AE5))} -> KRTS-APWN26-GETKRTSFUT6451
A6: SZAF | B6: 5115513594 | C6: 04.08.2026 | D6: 15.10.2026 | E6: 10337044 | F6: UNITED TEXTILE MILLS PRIVATE LIMITE | G6: 5 | H6: 8909490275962 | I6: 441814970005 | J6: KRTS-APWN26-GETKRTSFUT6, LIME GREEN, 2XL | L6: EA | M6: 1 | N6: 96 | O6: 96 | Q6: 276.7 | R6: 276.7 | S6: 1328.16 | T6: 26563.2 | U6: 5 | V6: INR | X6: =IF(ISNUMBER(VALUE(LEFT(J6,1))),LEFT(J6,MIN(IFERROR(FIND("A",UPPER(J6)),LEN(J6)+1),IFERROR(FIND("B",UPPER(J6)),LEN(J6)+1),IFERROR(FIND("C",UPPER(J6)),LEN(J6)+1),IFERROR(FIND("D",UPPER(J6)),LEN(J6)+1),IFERROR(FIND("E",UPPER(J6)),LEN(J6)+1),IFERROR(FIND("F",UPPER(J6)),LEN(J6)+1),IFERROR(FIND("G",UPPER(J6)),LEN(J6)+1),IFERROR(FIND("H",UPPER(J6)),LEN(J6)+1),IFERROR(FIND("I",UPPER(J6)),LEN(J6)+1),IFERROR(FIND("J",UPPER(J6)),LEN(J6)+1),IFERROR(FIND("K",UPPER(J6)),LEN(J6)+1),IFERROR(FIND("L",UPPER(J6)),LEN(J6)+1),IFERROR(FIND("M",UPPER(J6)),LEN(J6)+1),IFERROR(FIND("N",UPPER(J6)),LEN(J6)+1),IFERROR(FIND("O",UPPER(J6)),LEN(J6)+1),IFERROR(FIND("P",UPPER(J6)),LEN(J6)+1),IFERROR(FIND("Q",UPPER(J6)),LEN(J6)+1),IFERROR(FIND("R",UPPER(J6)),LEN(J6)+1),IFERROR(FIND("S",UPPER(J6)),LEN(J6)+1),IFERROR(FIND("T",UPPER(J6)),LEN(J6)+1),IFERROR(FIND("U",UPPER(J6)),LEN(J6)+1),IFERROR(FIND("V",UPPER(J6)),LEN(J6)+1),IFERROR(FIND("W",UPPER(J6)),LEN(J6)+1),IFERROR(FIND("X",UPPER(J6)),LEN(J6)+1),IFERROR(FIND("Y",UPPER(J6)),LEN(J6)+1),IFERROR(FIND("Z",UPPER(J6)),LEN(J6)+1))-1),LEFT(TEXT(I6,"0"),LEN(TEXT(I6,"0"))-3)) -> 441814970 | Y6: =IF(ISNUMBER(SEARCH("(RP)",J6)),"RP","DC") -> DC | Z6: =IF(ISNUMBER(SEARCH("(RP)",J6)),O6,IF(RIGHT(TRIM(J6),3)=", S",O6,0)) -> 0 | AA6: =IF(ISNUMBER(SEARCH("(RP)",J6)),O6,IF(RIGHT(TRIM(J6),3)=", M",O6,0)) -> 0 | AB6: =IF(ISNUMBER(SEARCH("(RP)",J6)),O6,IF(RIGHT(TRIM(J6),3)=", L",O6,0)) -> 0 | AC6: =IF(ISNUMBER(SEARCH("(RP)",J6)),O6,IF(RIGHT(TRIM(J6),4)=", XL",O6,0)) -> 0 | AD6: =IF(ISNUMBER(SEARCH("(RP)",J6)),O6,IF(OR(RIGHT(TRIM(J6),5)=", XXL",RIGHT(TRIM(J6),5)=", 2XL"),O6,0)) -> 96 | AE6: {=IFERROR(_xlfn.XLOOKUP(H6,Sheet1!$G:$G,Sheet1!$F:$F),IFERROR(_xlfn.XLOOKUP(1,(--($X$2:$X$1074=X6))*(--ISNUMBER(MATCH($H$2:$H$1074,Sheet1!$G:$G,0))),_xlfn.XLOOKUP($H$2:$H$1074,Sheet1!$G:$G,Sheet1!$F:$F,"")),"NOT FOUND"))} -> GETKRTSFUT6451 | AF6: =IFERROR(IF(ISNUMBER(SEARCH("(RP)",J6)),TRIM(SUBSTITUTE(MID(J6,10,LEN(J6)),"(RP)","")),TRIM(MID(J6,FIND(",",J6)+1,FIND(",",J6,FIND(",",J6)+1)-FIND(",",J6)-1))),"") -> LIME GREEN | AG6: =IF(A6="SZAF","Bangalore",IF(A6="SAEX","JHAJJAR",IF(A6="S0EU","HARIPAL",""))) -> Bangalore | AH6: {=IF(OR(J6="",AE6="",AE6="NOT FOUND"),"",IF(Y6="RP",_xlfn.LET(_xlpm.desc,_xlfn.XLOOKUP(1,(--(Sheet1!$F$2:$F$754=AE6))*(--ISNUMBER(FIND("-",Sheet1!$W$2:$W$754,FIND("-",Sheet1!$W$2:$W$754)+1))),Sheet1!$W$2:$W$754,""),IF(_xlpm.desc="","NOT FOUND",LEFT(_xlpm.desc,FIND("-",_xlpm.desc,FIND("-",_xlpm.desc)+1))&AE6)),LEFT(J6,FIND("-",J6,FIND("-",J6)+1))&AE6))} -> KRTS-APWN26-GETKRTSFUT6451
A7: SZAF | B7: 5115513593 | C7: 04.08.2026 | D7: 30.11.2026 | E7: 10337044 | F7: UNITED TEXTILE MILLS PRIVATE LIMITE | G7: 1 | H7: 8909490275566 | I7: 441814969001 | J7: KRTS-APWN26-GETKRTSFUT6422, DARK GREY, S | L7: EA | M7: 1 | N7: 64 | O7: 64 | Q7: 279.7 | R7: 279.7 | S7: 895.04 | T7: 17900.8 | U7: 5 | V7: INR | X7: =IF(ISNUMBER(VALUE(LEFT(J7,1))),LEFT(J7,MIN(IFERROR(FIND("A",UPPER(J7)),LEN(J7)+1),IFERROR(FIND("B",UPPER(J7)),LEN(J7)+1),IFERROR(FIND("C",UPPER(J7)),LEN(J7)+1),IFERROR(FIND("D",UPPER(J7)),LEN(J7)+1),IFERROR(FIND("E",UPPER(J7)),LEN(J7)+1),IFERROR(FIND("F",UPPER(J7)),LEN(J7)+1),IFERROR(FIND("G",UPPER(J7)),LEN(J7)+1),IFERROR(FIND("H",UPPER(J7)),LEN(J7)+1),IFERROR(FIND("I",UPPER(J7)),LEN(J7)+1),IFERROR(FIND("J",UPPER(J7)),LEN(J7)+1),IFERROR(FIND("K",UPPER(J7)),LEN(J7)+1),IFERROR(FIND("L",UPPER(J7)),LEN(J7)+1),IFERROR(FIND("M",UPPER(J7)),LEN(J7)+1),IFERROR(FIND("N",UPPER(J7)),LEN(J7)+1),IFERROR(FIND("O",UPPER(J7)),LEN(J7)+1),IFERROR(FIND("P",UPPER(J7)),LEN(J7)+1),IFERROR(FIND("Q",UPPER(J7)),LEN(J7)+1),IFERROR(FIND("R",UPPER(J7)),LEN(J7)+1),IFERROR(FIND("S",UPPER(J7)),LEN(J7)+1),IFERROR(FIND("T",UPPER(J7)),LEN(J7)+1),IFERROR(FIND("U",UPPER(J7)),LEN(J7)+1),IFERROR(FIND("V",UPPER(J7)),LEN(J7)+1),IFERROR(FIND("W",UPPER(J7)),LEN(J7)+1),IFERROR(FIND("X",UPPER(J7)),LEN(J7)+1),IFERROR(FIND("Y",UPPER(J7)),LEN(J7)+1),IFERROR(FIND("Z",UPPER(J7)),LEN(J7)+1))-1),LEFT(TEXT(I7,"0"),LEN(TEXT(I7,"0"))-3)) -> 441814969 | Y7: =IF(ISNUMBER(SEARCH("(RP)",J7)),"RP","DC") -> DC | Z7: =IF(ISNUMBER(SEARCH("(RP)",J7)),O7,IF(RIGHT(TRIM(J7),3)=", S",O7,0)) -> 64 | AA7: =IF(ISNUMBER(SEARCH("(RP)",J7)),O7,IF(RIGHT(TRIM(J7),3)=", M",O7,0)) -> 0 | AB7: =IF(ISNUMBER(SEARCH("(RP)",J7)),O7,IF(RIGHT(TRIM(J7),3)=", L",O7,0)) -> 0 | AC7: =IF(ISNUMBER(SEARCH("(RP)",J7)),O7,IF(RIGHT(TRIM(J7),4)=", XL",O7,0)) -> 0 | AD7: =IF(ISNUMBER(SEARCH("(RP)",J7)),O7,IF(OR(RIGHT(TRIM(J7),5)=", XXL",RIGHT(TRIM(J7),5)=", 2XL"),O7,0)) -> 0 | AE7: {=IFERROR(_xlfn.XLOOKUP(H7,Sheet1!$G:$G,Sheet1!$F:$F),IFERROR(_xlfn.XLOOKUP(1,(--($X$2:$X$1074=X7))*(--ISNUMBER(MATCH($H$2:$H$1074,Sheet1!$G:$G,0))),_xlfn.XLOOKUP($H$2:$H$1074,Sheet1!$G:$G,Sheet1!$F:$F,"")),"NOT FOUND"))} -> GETKRTSFUT6422 | AF7: =IFERROR(IF(ISNUMBER(SEARCH("(RP)",J7)),TRIM(SUBSTITUTE(MID(J7,10,LEN(J7)),"(RP)","")),TRIM(MID(J7,FIND(",",J7)+1,FIND(",",J7,FIND(",",J7)+1)-FIND(",",J7)-1))),"") -> DARK GREY | AG7: =IF(A7="SZAF","Bangalore",IF(A7="SAEX","JHAJJAR",IF(A7="S0EU","HARIPAL",""))) -> Bangalore | AH7: {=IF(OR(J7="",AE7="",AE7="NOT FOUND"),"",IF(Y7="RP",_xlfn.LET(_xlpm.desc,_xlfn.XLOOKUP(1,(--(Sheet1!$F$2:$F$754=AE7))*(--ISNUMBER(FIND("-",Sheet1!$W$2:$W$754,FIND("-",Sheet1!$W$2:$W$754)+1))),Sheet1!$W$2:$W$754,""),IF(_xlpm.desc="","NOT FOUND",LEFT(_xlpm.desc,FIND("-",_xlpm.desc,FIND("-",_xlpm.desc)+1))&AE7)),LEFT(J7,FIND("-",J7,FIND("-",J7)+1))&AE7))} -> KRTS-APWN26-GETKRTSFUT6422
A8: SZAF | B8: 5115513593 | C8: 04.08.2026 | D8: 30.11.2026 | E8: 10337044 | F8: UNITED TEXTILE MILLS PRIVATE LIMITE | G8: 2 | H8: 8909490275863 | I8: 441814969002 | J8: KRTS-APWN26-GETKRTSFUT6422, DARK GREY, M | L8: EA | M8: 1 | N8: 273 | O8: 273 | Q8: 279.7 | R8: 279.7 | S8: 3817.91 | T8: 76358.1 | U8: 5 | V8: INR | X8: =IF(ISNUMBER(VALUE(LEFT(J8,1))),LEFT(J8,MIN(IFERROR(FIND("A",UPPER(J8)),LEN(J8)+1),IFERROR(FIND("B",UPPER(J8)),LEN(J8)+1),IFERROR(FIND("C",UPPER(J8)),LEN(J8)+1),IFERROR(FIND("D",UPPER(J8)),LEN(J8)+1),IFERROR(FIND("E",UPPER(J8)),LEN(J8)+1),IFERROR(FIND("F",UPPER(J8)),LEN(J8)+1),IFERROR(FIND("G",UPPER(J8)),LEN(J8)+1),IFERROR(FIND("H",UPPER(J8)),LEN(J8)+1),IFERROR(FIND("I",UPPER(J8)),LEN(J8)+1),IFERROR(FIND("J",UPPER(J8)),LEN(J8)+1),IFERROR(FIND("K",UPPER(J8)),LEN(J8)+1),IFERROR(FIND("L",UPPER(J8)),LEN(J8)+1),IFERROR(FIND("M",UPPER(J8)),LEN(J8)+1),IFERROR(FIND("N",UPPER(J8)),LEN(J8)+1),IFERROR(FIND("O",UPPER(J8)),LEN(J8)+1),IFERROR(FIND("P",UPPER(J8)),LEN(J8)+1),IFERROR(FIND("Q",UPPER(J8)),LEN(J8)+1),IFERROR(FIND("R",UPPER(J8)),LEN(J8)+1),IFERROR(FIND("S",UPPER(J8)),LEN(J8)+1),IFERROR(FIND("T",UPPER(J8)),LEN(J8)+1),IFERROR(FIND("U",UPPER(J8)),LEN(J8)+1),IFERROR(FIND("V",UPPER(J8)),LEN(J8)+1),IFERROR(FIND("W",UPPER(J8)),LEN(J8)+1),IFERROR(FIND("X",UPPER(J8)),LEN(J8)+1),IFERROR(FIND("Y",UPPER(J8)),LEN(J8)+1),IFERROR(FIND("Z",UPPER(J8)),LEN(J8)+1))-1),LEFT(TEXT(I8,"0"),LEN(TEXT(I8,"0"))-3)) -> 441814969 | Y8: =IF(ISNUMBER(SEARCH("(RP)",J8)),"RP","DC") -> DC | Z8: =IF(ISNUMBER(SEARCH("(RP)",J8)),O8,IF(RIGHT(TRIM(J8),3)=", S",O8,0)) -> 0 | AA8: =IF(ISNUMBER(SEARCH("(RP)",J8)),O8,IF(RIGHT(TRIM(J8),3)=", M",O8,0)) -> 273 | AB8: =IF(ISNUMBER(SEARCH("(RP)",J8)),O8,IF(RIGHT(TRIM(J8),3)=", L",O8,0)) -> 0 | AC8: =IF(ISNUMBER(SEARCH("(RP)",J8)),O8,IF(RIGHT(TRIM(J8),4)=", XL",O8,0)) -> 0 | AD8: =IF(ISNUMBER(SEARCH("(RP)",J8)),O8,IF(OR(RIGHT(TRIM(J8),5)=", XXL",RIGHT(TRIM(J8),5)=", 2XL"),O8,0)) -> 0 | AE8: {=IFERROR(_xlfn.XLOOKUP(H8,Sheet1!$G:$G,Sheet1!$F:$F),IFERROR(_xlfn.XLOOKUP(1,(--($X$2:$X$1074=X8))*(--ISNUMBER(MATCH($H$2:$H$1074,Sheet1!$G:$G,0))),_xlfn.XLOOKUP($H$2:$H$1074,Sheet1!$G:$G,Sheet1!$F:$F,"")),"NOT FOUND"))} -> GETKRTSFUT6422 | AF8: =IFERROR(IF(ISNUMBER(SEARCH("(RP)",J8)),TRIM(SUBSTITUTE(MID(J8,10,LEN(J8)),"(RP)","")),TRIM(MID(J8,FIND(",",J8)+1,FIND(",",J8,FIND(",",J8)+1)-FIND(",",J8)-1))),"") -> DARK GREY | AG8: =IF(A8="SZAF","Bangalore",IF(A8="SAEX","JHAJJAR",IF(A8="S0EU","HARIPAL",""))) -> Bangalore | AH8: {=IF(OR(J8="",AE8="",AE8="NOT FOUND"),"",IF(Y8="RP",_xlfn.LET(_xlpm.desc,_xlfn.XLOOKUP(1,(--(Sheet1!$F$2:$F$754=AE8))*(--ISNUMBER(FIND("-",Sheet1!$W$2:$W$754,FIND("-",Sheet1!$W$2:$W$754)+1))),Sheet1!$W$2:$W$754,""),IF(_xlpm.desc="","NOT FOUND",LEFT(_xlpm.desc,FIND("-",_xlpm.desc,FIND("-",_xlpm.desc)+1))&AE8)),LEFT(J8,FIND("-",J8,FIND("-",J8)+1))&AE8))} -> KRTS-APWN26-GETKRTSFUT6422
A9: SZAF | B9: 5115513593 | C9: 04.08.2026 | D9: 30.11.2026 | E9: 10337044 | F9: UNITED TEXTILE MILLS PRIVATE LIMITE | G9: 3 | H9: 8909490275870 | I9: 441814969003 | J9: KRTS-APWN26-GETKRTSFUT6422, DARK GREY, L | L9: EA | M9: 1 | N9: 257 | O9: 257 | Q9: 279.7 | R9: 279.7 | S9: 3594.15 | T9: 71882.9 | U9: 5 | V9: INR | X9: =IF(ISNUMBER(VALUE(LEFT(J9,1))),LEFT(J9,MIN(IFERROR(FIND("A",UPPER(J9)),LEN(J9)+1),IFERROR(FIND("B",UPPER(J9)),LEN(J9)+1),IFERROR(FIND("C",UPPER(J9)),LEN(J9)+1),IFERROR(FIND("D",UPPER(J9)),LEN(J9)+1),IFERROR(FIND("E",UPPER(J9)),LEN(J9)+1),IFERROR(FIND("F",UPPER(J9)),LEN(J9)+1),IFERROR(FIND("G",UPPER(J9)),LEN(J9)+1),IFERROR(FIND("H",UPPER(J9)),LEN(J9)+1),IFERROR(FIND("I",UPPER(J9)),LEN(J9)+1),IFERROR(FIND("J",UPPER(J9)),LEN(J9)+1),IFERROR(FIND("K",UPPER(J9)),LEN(J9)+1),IFERROR(FIND("L",UPPER(J9)),LEN(J9)+1),IFERROR(FIND("M",UPPER(J9)),LEN(J9)+1),IFERROR(FIND("N",UPPER(J9)),LEN(J9)+1),IFERROR(FIND("O",UPPER(J9)),LEN(J9)+1),IFERROR(FIND("P",UPPER(J9)),LEN(J9)+1),IFERROR(FIND("Q",UPPER(J9)),LEN(J9)+1),IFERROR(FIND("R",UPPER(J9)),LEN(J9)+1),IFERROR(FIND("S",UPPER(J9)),LEN(J9)+1),IFERROR(FIND("T",UPPER(J9)),LEN(J9)+1),IFERROR(FIND("U",UPPER(J9)),LEN(J9)+1),IFERROR(FIND("V",UPPER(J9)),LEN(J9)+1),IFERROR(FIND("W",UPPER(J9)),LEN(J9)+1),IFERROR(FIND("X",UPPER(J9)),LEN(J9)+1),IFERROR(FIND("Y",UPPER(J9)),LEN(J9)+1),IFERROR(FIND("Z",UPPER(J9)),LEN(J9)+1))-1),LEFT(TEXT(I9,"0"),LEN(TEXT(I9,"0"))-3)) -> 441814969 | Y9: =IF(ISNUMBER(SEARCH("(RP)",J9)),"RP","DC") -> DC | Z9: =IF(ISNUMBER(SEARCH("(RP)",J9)),O9,IF(RIGHT(TRIM(J9),3)=", S",O9,0)) -> 0 | AA9: =IF(ISNUMBER(SEARCH("(RP)",J9)),O9,IF(RIGHT(TRIM(J9),3)=", M",O9,0)) -> 0 | AB9: =IF(ISNUMBER(SEARCH("(RP)",J9)),O9,IF(RIGHT(TRIM(J9),3)=", L",O9,0)) -> 257 | AC9: =IF(ISNUMBER(SEARCH("(RP)",J9)),O9,IF(RIGHT(TRIM(J9),4)=", XL",O9,0)) -> 0 | AD9: =IF(ISNUMBER(SEARCH("(RP)",J9)),O9,IF(OR(RIGHT(TRIM(J9),5)=", XXL",RIGHT(TRIM(J9),5)=", 2XL"),O9,0)) -> 0 | AE9: {=IFERROR(_xlfn.XLOOKUP(H9,Sheet1!$G:$G,Sheet1!$F:$F),IFERROR(_xlfn.XLOOKUP(1,(--($X$2:$X$1074=X9))*(--ISNUMBER(MATCH($H$2:$H$1074,Sheet1!$G:$G,0))),_xlfn.XLOOKUP($H$2:$H$1074,Sheet1!$G:$G,Sheet1!$F:$F,"")),"NOT FOUND"))} -> GETKRTSFUT6422 | AF9: =IFERROR(IF(ISNUMBER(SEARCH("(RP)",J9)),TRIM(SUBSTITUTE(MID(J9,10,LEN(J9)),"(RP)","")),TRIM(MID(J9,FIND(",",J9)+1,FIND(",",J9,FIND(",",J9)+1)-FIND(",",J9)-1))),"") -> DARK GREY | AG9: =IF(A9="SZAF","Bangalore",IF(A9="SAEX","JHAJJAR",IF(A9="S0EU","HARIPAL",""))) -> Bangalore | AH9: {=IF(OR(J9="",AE9="",AE9="NOT FOUND"),"",IF(Y9="RP",_xlfn.LET(_xlpm.desc,_xlfn.XLOOKUP(1,(--(Sheet1!$F$2:$F$754=AE9))*(--ISNUMBER(FIND("-",Sheet1!$W$2:$W$754,FIND("-",Sheet1!$W$2:$W$754)+1))),Sheet1!$W$2:$W$754,""),IF(_xlpm.desc="","NOT FOUND",LEFT(_xlpm.desc,FIND("-",_xlpm.desc,FIND("-",_xlpm.desc)+1))&AE9)),LEFT(J9,FIND("-",J9,FIND("-",J9)+1))&AE9))} -> KRTS-APWN26-GETKRTSFUT6422
A10: SZAF | B10: 5115513593 | C10: 04.08.2026 | D10: 30.11.2026 | E10: 10337044 | F10: UNITED TEXTILE MILLS PRIVATE LIMITE | G10: 4 | H10: 8909490275887 | I10: 441814969004 | J10: KRTS-APWN26-GETKRTSFUT642, DARK GREY, XL | L10: EA | M10: 1 | N10: 273 | O10: 273 | Q10: 279.7 | R10: 279.7 | S10: 3817.91 | T10: 76358.1 | U10: 5 | V10: INR | X10: =IF(ISNUMBER(VALUE(LEFT(J10,1))),LEFT(J10,MIN(IFERROR(FIND("A",UPPER(J10)),LEN(J10)+1),IFERROR(FIND("B",UPPER(J10)),LEN(J10)+1),IFERROR(FIND("C",UPPER(J10)),LEN(J10)+1),IFERROR(FIND("D",UPPER(J10)),LEN(J10)+1),IFERROR(FIND("E",UPPER(J10)),LEN(J10)+1),IFERROR(FIND("F",UPPER(J10)),LEN(J10)+1),IFERROR(FIND("G",UPPER(J10)),LEN(J10)+1),IFERROR(FIND("H",UPPER(J10)),LEN(J10)+1),IFERROR(FIND("I",UPPER(J10)),LEN(J10)+1),IFERROR(FIND("J",UPPER(J10)),LEN(J10)+1),IFERROR(FIND("K",UPPER(J10)),LEN(J10)+1),IFERROR(FIND("L",UPPER(J10)),LEN(J10)+1),IFERROR(FIND("M",UPPER(J10)),LEN(J10)+1),IFERROR(FIND("N",UPPER(J10)),LEN(J10)+1),IFERROR(FIND("O",UPPER(J10)),LEN(J10)+1),IFERROR(FIND("P",UPPER(J10)),LEN(J10)+1),IFERROR(FIND("Q",UPPER(J10)),LEN(J10)+1),IFERROR(FIND("R",UPPER(J10)),LEN(J10)+1),IFERROR(FIND("S",UPPER(J10)),LEN(J10)+1),IFERROR(FIND("T",UPPER(J10)),LEN(J10)+1),IFERROR(FIND("U",UPPER(J10)),LEN(J10)+1),IFERROR(FIND("V",UPPER(J10)),LEN(J10)+1),IFERROR(FIND("W",UPPER(J10)),LEN(J10)+1),IFERROR(FIND("X",UPPER(J10)),LEN(J10)+1),IFERROR(FIND("Y",UPPER(J10)),LEN(J10)+1),IFERROR(FIND("Z",UPPER(J10)),LEN(J10)+1))-1),LEFT(TEXT(I10,"0"),LEN(TEXT(I10,"0"))-3)) -> 441814969 | Y10: =IF(ISNUMBER(SEARCH("(RP)",J10)),"RP","DC") -> DC | Z10: =IF(ISNUMBER(SEARCH("(RP)",J10)),O10,IF(RIGHT(TRIM(J10),3)=", S",O10,0)) -> 0 | AA10: =IF(ISNUMBER(SEARCH("(RP)",J10)),O10,IF(RIGHT(TRIM(J10),3)=", M",O10,0)) -> 0 | AB10: =IF(ISNUMBER(SEARCH("(RP)",J10)),O10,IF(RIGHT(TRIM(J10),3)=", L",O10,0)) -> 0 | AC10: =IF(ISNUMBER(SEARCH("(RP)",J10)),O10,IF(RIGHT(TRIM(J10),4)=", XL",O10,0)) -> 273 | AD10: =IF(ISNUMBER(SEARCH("(RP)",J10)),O10,IF(OR(RIGHT(TRIM(J10),5)=", XXL",RIGHT(TRIM(J10),5)=", 2XL"),O10,0)) -> 0 | AE10: {=IFERROR(_xlfn.XLOOKUP(H10,Sheet1!$G:$G,Sheet1!$F:$F),IFERROR(_xlfn.XLOOKUP(1,(--($X$2:$X$1074=X10))*(--ISNUMBER(MATCH($H$2:$H$1074,Sheet1!$G:$G,0))),_xlfn.XLOOKUP($H$2:$H$1074,Sheet1!$G:$G,Sheet1!$F:$F,"")),"NOT FOUND"))} -> GETKRTSFUT6422 | AF10: =IFERROR(IF(ISNUMBER(SEARCH("(RP)",J10)),TRIM(SUBSTITUTE(MID(J10,10,LEN(J10)),"(RP)","")),TRIM(MID(J10,FIND(",",J10)+1,FIND(",",J10,FIND(",",J10)+1)-FIND(",",J10)-1))),"") -> DARK GREY | AG10: =IF(A10="SZAF","Bangalore",IF(A10="SAEX","JHAJJAR",IF(A10="S0EU","HARIPAL",""))) -> Bangalore | AH10: {=IF(OR(J10="",AE10="",AE10="NOT FOUND"),"",IF(Y10="RP",_xlfn.LET(_xlpm.desc,_xlfn.XLOOKUP(1,(--(Sheet1!$F$2:$F$754=AE10))*(--ISNUMBER(FIND("-",Sheet1!$W$2:$W$754,FIND("-",Sheet1!$W$2:$W$754)+1))),Sheet1!$W$2:$W$754,""),IF(_xlpm.desc="","NOT FOUND",LEFT(_xlpm.desc,FIND("-",_xlpm.desc,FIND("-",_xlpm.desc)+1))&AE10)),LEFT(J10,FIND("-",J10,FIND("-",J10)+1))&AE10))} -> KRTS-APWN26-GETKRTSFUT6422
A11: SZAF | B11: 5115513593 | C11: 04.08.2026 | D11: 30.11.2026 | E11: 10337044 | F11: UNITED TEXTILE MILLS PRIVATE LIMITE | G11: 5 | H11: 8909490275900 | I11: 441814969005 | J11: KRTS-APWN26-GETKRTSFUT64, DARK GREY, 2XL | L11: EA | M11: 1 | N11: 96 | O11: 96 | Q11: 279.7 | R11: 279.7 | S11: 1342.56 | T11: 26851.2 | U11: 5 | V11: INR | X11: =IF(ISNUMBER(VALUE(LEFT(J11,1))),LEFT(J11,MIN(IFERROR(FIND("A",UPPER(J11)),LEN(J11)+1),IFERROR(FIND("B",UPPER(J11)),LEN(J11)+1),IFERROR(FIND("C",UPPER(J11)),LEN(J11)+1),IFERROR(FIND("D",UPPER(J11)),LEN(J11)+1),IFERROR(FIND("E",UPPER(J11)),LEN(J11)+1),IFERROR(FIND("F",UPPER(J11)),LEN(J11)+1),IFERROR(FIND("G",UPPER(J11)),LEN(J11)+1),IFERROR(FIND("H",UPPER(J11)),LEN(J11)+1),IFERROR(FIND("I",UPPER(J11)),LEN(J11)+1),IFERROR(FIND("J",UPPER(J11)),LEN(J11)+1),IFERROR(FIND("K",UPPER(J11)),LEN(J11)+1),IFERROR(FIND("L",UPPER(J11)),LEN(J11)+1),IFERROR(FIND("M",UPPER(J11)),LEN(J11)+1),IFERROR(FIND("N",UPPER(J11)),LEN(J11)+1),IFERROR(FIND("O",UPPER(J11)),LEN(J11)+1),IFERROR(FIND("P",UPPER(J11)),LEN(J11)+1),IFERROR(FIND("Q",UPPER(J11)),LEN(J11)+1),IFERROR(FIND("R",UPPER(J11)),LEN(J11)+1),IFERROR(FIND("S",UPPER(J11)),LEN(J11)+1),IFERROR(FIND("T",UPPER(J11)),LEN(J11)+1),IFERROR(FIND("U",UPPER(J11)),LEN(J11)+1),IFERROR(FIND("V",UPPER(J11)),LEN(J11)+1),IFERROR(FIND("W",UPPER(J11)),LEN(J11)+1),IFERROR(FIND("X",UPPER(J11)),LEN(J11)+1),IFERROR(FIND("Y",UPPER(J11)),LEN(J11)+1),IFERROR(FIND("Z",UPPER(J11)),LEN(J11)+1))-1),LEFT(TEXT(I11,"0"),LEN(TEXT(I11,"0"))-3)) -> 441814969 | Y11: =IF(ISNUMBER(SEARCH("(RP)",J11)),"RP","DC") -> DC | Z11: =IF(ISNUMBER(SEARCH("(RP)",J11)),O11,IF(RIGHT(TRIM(J11),3)=", S",O11,0)) -> 0 | AA11: =IF(ISNUMBER(SEARCH("(RP)",J11)),O11,IF(RIGHT(TRIM(J11),3)=", M",O11,0)) -> 0 | AB11: =IF(ISNUMBER(SEARCH("(RP)",J11)),O11,IF(RIGHT(TRIM(J11),3)=", L",O11,0)) -> 0 | AC11: =IF(ISNUMBER(SEARCH("(RP)",J11)),O11,IF(RIGHT(TRIM(J11),4)=", XL",O11,0)) -> 0 | AD11: =IF(ISNUMBER(SEARCH("(RP)",J11)),O11,IF(OR(RIGHT(TRIM(J11),5)=", XXL",RIGHT(TRIM(J11),5)=", 2XL"),O11,0)) -> 96 | AE11: {=IFERROR(_xlfn.XLOOKUP(H11,Sheet1!$G:$G,Sheet1!$F:$F),IFERROR(_xlfn.XLOOKUP(1,(--($X$2:$X$1074=X11))*(--ISNUMBER(MATCH($H$2:$H$1074,Sheet1!$G:$G,0))),_xlfn.XLOOKUP($H$2:$H$1074,Sheet1!$G:$G,Sheet1!$F:$F,"")),"NOT FOUND"))} -> GETKRTSFUT6422 | AF11: =IFERROR(IF(ISNUMBER(SEARCH("(RP)",J11)),TRIM(SUBSTITUTE(MID(J11,10,LEN(J11)),"(RP)","")),TRIM(MID(J11,FIND(",",J11)+1,FIND(",",J11,FIND(",",J11)+1)-FIND(",",J11)-1))),"") -> DARK GREY | AG11: =IF(A11="SZAF","Bangalore",IF(A11="SAEX","JHAJJAR",IF(A11="S0EU","HARIPAL",""))) -> Bangalore | AH11: {=IF(OR(J11="",AE11="",AE11="NOT FOUND"),"",IF(Y11="RP",_xlfn.LET(_xlpm.desc,_xlfn.XLOOKUP(1,(--(Sheet1!$F$2:$F$754=AE11))*(--ISNUMBER(FIND("-",Sheet1!$W$2:$W$754,FIND("-",Sheet1!$W$2:$W$754)+1))),Sheet1!$W$2:$W$754,""),IF(_xlpm.desc="","NOT FOUND",LEFT(_xlpm.desc,FIND("-",_xlpm.desc,FIND("-",_xlpm.desc)+1))&AE11)),LEFT(J11,FIND("-",J11,FIND("-",J11)+1))&AE11))} -> KRTS-APWN26-GETKRTSFUT6422
A12: SZAF | B12: 5115513592 | C12: 04.08.2026 | D12: 30.11.2026 | E12: 10337044 | F12: UNITED TEXTILE MILLS PRIVATE LIMITE | G12: 1 | H12: 8909490275511 | I12: 441814968001 | J12: KRTS-APWN26-GETKRTSFUT6421, DARK GREY, S | L12: EA | M12: 1 | N12: 64 | O12: 64 | Q12: 276.7 | R12: 276.7 | S12: 885.44 | T12: 17708.8 | U12: 5 | V12: INR | X12: =IF(ISNUMBER(VALUE(LEFT(J12,1))),LEFT(J12,MIN(IFERROR(FIND("A",UPPER(J12)),LEN(J12)+1),IFERROR(FIND("B",UPPER(J12)),LEN(J12)+1),IFERROR(FIND("C",UPPER(J12)),LEN(J12)+1),IFERROR(FIND("D",UPPER(J12)),LEN(J12)+1),IFERROR(FIND("E",UPPER(J12)),LEN(J12)+1),IFERROR(FIND("F",UPPER(J12)),LEN(J12)+1),IFERROR(FIND("G",UPPER(J12)),LEN(J12)+1),IFERROR(FIND("H",UPPER(J12)),LEN(J12)+1),IFERROR(FIND("I",UPPER(J12)),LEN(J12)+1),IFERROR(FIND("J",UPPER(J12)),LEN(J12)+1),IFERROR(FIND("K",UPPER(J12)),LEN(J12)+1),IFERROR(FIND("L",UPPER(J12)),LEN(J12)+1),IFERROR(FIND("M",UPPER(J12)),LEN(J12)+1),IFERROR(FIND("N",UPPER(J12)),LEN(J12)+1),IFERROR(FIND("O",UPPER(J12)),LEN(J12)+1),IFERROR(FIND("P",UPPER(J12)),LEN(J12)+1),IFERROR(FIND("Q",UPPER(J12)),LEN(J12)+1),IFERROR(FIND("R",UPPER(J12)),LEN(J12)+1),IFERROR(FIND("S",UPPER(J12)),LEN(J12)+1),IFERROR(FIND("T",UPPER(J12)),LEN(J12)+1),IFERROR(FIND("U",UPPER(J12)),LEN(J12)+1),IFERROR(FIND("V",UPPER(J12)),LEN(J12)+1),IFERROR(FIND("W",UPPER(J12)),LEN(J12)+1),IFERROR(FIND("X",UPPER(J12)),LEN(J12)+1),IFERROR(FIND("Y",UPPER(J12)),LEN(J12)+1),IFERROR(FIND("Z",UPPER(J12)),LEN(J12)+1))-1),LEFT(TEXT(I12,"0"),LEN(TEXT(I12,"0"))-3)) -> 441814968 | Y12: =IF(ISNUMBER(SEARCH("(RP)",J12)),"RP","DC") -> DC | Z12: =IF(ISNUMBER(SEARCH("(RP)",J12)),O12,IF(RIGHT(TRIM(J12),3)=", S",O12,0)) -> 64 | AA12: =IF(ISNUMBER(SEARCH("(RP)",J12)),O12,IF(RIGHT(TRIM(J12),3)=", M",O12,0)) -> 0 | AB12: =IF(ISNUMBER(SEARCH("(RP)",J12)),O12,IF(RIGHT(TRIM(J12),3)=", L",O12,0)) -> 0 | AC12: =IF(ISNUMBER(SEARCH("(RP)",J12)),O12,IF(RIGHT(TRIM(J12),4)=", XL",O12,0)) -> 0 | AD12: =IF(ISNUMBER(SEARCH("(RP)",J12)),O12,IF(OR(RIGHT(TRIM(J12),5)=", XXL",RIGHT(TRIM(J12),5)=", 2XL"),O12,0)) -> 0 | AE12: {=IFERROR(_xlfn.XLOOKUP(H12,Sheet1!$G:$G,Sheet1!$F:$F),IFERROR(_xlfn.XLOOKUP(1,(--($X$2:$X$1074=X12))*(--ISNUMBER(MATCH($H$2:$H$1074,Sheet1!$G:$G,0))),_xlfn.XLOOKUP($H$2:$H$1074,Sheet1!$G:$G,Sheet1!$F:$F,"")),"NOT FOUND"))} -> GETKRTSFUT6421 | AF12: =IFERROR(IF(ISNUMBER(SEARCH("(RP)",J12)),TRIM(SUBSTITUTE(MID(J12,10,LEN(J12)),"(RP)","")),TRIM(MID(J12,FIND(",",J12)+1,FIND(",",J12,FIND(",",J12)+1)-FIND(",",J12)-1))),"") -> DARK GREY | AG12: =IF(A12="SZAF","Bangalore",IF(A12="SAEX","JHAJJAR",IF(A12="S0EU","HARIPAL",""))) -> Bangalore | AH12: {=IF(OR(J12="",AE12="",AE12="NOT FOUND"),"",IF(Y12="RP",_xlfn.LET(_xlpm.desc,_xlfn.XLOOKUP(1,(--(Sheet1!$F$2:$F$754=AE12))*(--ISNUMBER(FIND("-",Sheet1!$W$2:$W$754,FIND("-",Sheet1!$W$2:$W$754)+1))),Sheet1!$W$2:$W$754,""),IF(_xlpm.desc="","NOT FOUND",LEFT(_xlpm.desc,FIND("-",_xlpm.desc,FIND("-",_xlpm.desc)+1))&AE12)),LEFT(J12,FIND("-",J12,FIND("-",J12)+1))&AE12))} -> KRTS-APWN26-GETKRTSFUT6421
A13: SZAF | B13: 5115513592 | C13: 04.08.2026 | D13: 30.11.2026 | E13: 10337044 | F13: UNITED TEXTILE MILLS PRIVATE LIMITE | G13: 2 | H13: 8909490275528 | I13: 441814968002 | J13: KRTS-APWN26-GETKRTSFUT6421, DARK GREY, M | L13: EA | M13: 1 | N13: 273 | O13: 273 | Q13: 276.7 | R13: 276.7 | S13: 3776.96 | T13: 75539.1 | U13: 5 | V13: INR | X13: =IF(ISNUMBER(VALUE(LEFT(J13,1))),LEFT(J13,MIN(IFERROR(FIND("A",UPPER(J13)),LEN(J13)+1),IFERROR(FIND("B",UPPER(J13)),LEN(J13)+1),IFERROR(FIND("C",UPPER(J13)),LEN(J13)+1),IFERROR(FIND("D",UPPER(J13)),LEN(J13)+1),IFERROR(FIND("E",UPPER(J13)),LEN(J13)+1),IFERROR(FIND("F",UPPER(J13)),LEN(J13)+1),IFERROR(FIND("G",UPPER(J13)),LEN(J13)+1),IFERROR(FIND("H",UPPER(J13)),LEN(J13)+1),IFERROR(FIND("I",UPPER(J13)),LEN(J13)+1),IFERROR(FIND("J",UPPER(J13)),LEN(J13)+1),IFERROR(FIND("K",UPPER(J13)),LEN(J13)+1),IFERROR(FIND("L",UPPER(J13)),LEN(J13)+1),IFERROR(FIND("M",UPPER(J13)),LEN(J13)+1),IFERROR(FIND("N",UPPER(J13)),LEN(J13)+1),IFERROR(FIND("O",UPPER(J13)),LEN(J13)+1),IFERROR(FIND("P",UPPER(J13)),LEN(J13)+1),IFERROR(FIND("Q",UPPER(J13)),LEN(J13)+1),IFERROR(FIND("R",UPPER(J13)),LEN(J13)+1),IFERROR(FIND("S",UPPER(J13)),LEN(J13)+1),IFERROR(FIND("T",UPPER(J13)),LEN(J13)+1),IFERROR(FIND("U",UPPER(J13)),LEN(J13)+1),IFERROR(FIND("V",UPPER(J13)),LEN(J13)+1),IFERROR(FIND("W",UPPER(J13)),LEN(J13)+1),IFERROR(FIND("X",UPPER(J13)),LEN(J13)+1),IFERROR(FIND("Y",UPPER(J13)),LEN(J13)+1),IFERROR(FIND("Z",UPPER(J13)),LEN(J13)+1))-1),LEFT(TEXT(I13,"0"),LEN(TEXT(I13,"0"))-3)) -> 441814968 | Y13: =IF(ISNUMBER(SEARCH("(RP)",J13)),"RP","DC") -> DC | Z13: =IF(ISNUMBER(SEARCH("(RP)",J13)),O13,IF(RIGHT(TRIM(J13),3)=", S",O13,0)) -> 0 | AA13: =IF(ISNUMBER(SEARCH("(RP)",J13)),O13,IF(RIGHT(TRIM(J13),3)=", M",O13,0)) -> 273 | AB13: =IF(ISNUMBER(SEARCH("(RP)",J13)),O13,IF(RIGHT(TRIM(J13),3)=", L",O13,0)) -> 0 | AC13: =IF(ISNUMBER(SEARCH("(RP)",J13)),O13,IF(RIGHT(TRIM(J13),4)=", XL",O13,0)) -> 0 | AD13: =IF(ISNUMBER(SEARCH("(RP)",J13)),O13,IF(OR(RIGHT(TRIM(J13),5)=", XXL",RIGHT(TRIM(J13),5)=", 2XL"),O13,0)) -> 0 | AE13: {=IFERROR(_xlfn.XLOOKUP(H13,Sheet1!$G:$G,Sheet1!$F:$F),IFERROR(_xlfn.XLOOKUP(1,(--($X$2:$X$1074=X13))*(--ISNUMBER(MATCH($H$2:$H$1074,Sheet1!$G:$G,0))),_xlfn.XLOOKUP($H$2:$H$1074,Sheet1!$G:$G,Sheet1!$F:$F,"")),"NOT FOUND"))} -> GETKRTSFUT6421 | AF13: =IFERROR(IF(ISNUMBER(SEARCH("(RP)",J13)),TRIM(SUBSTITUTE(MID(J13,10,LEN(J13)),"(RP)","")),TRIM(MID(J13,FIND(",",J13)+1,FIND(",",J13,FIND(",",J13)+1)-FIND(",",J13)-1))),"") -> DARK GREY | AG13: =IF(A13="SZAF","Bangalore",IF(A13="SAEX","JHAJJAR",IF(A13="S0EU","HARIPAL",""))) -> Bangalore | AH13: {=IF(OR(J13="",AE13="",AE13="NOT FOUND"),"",IF(Y13="RP",_xlfn.LET(_xlpm.desc,_xlfn.XLOOKUP(1,(--(Sheet1!$F$2:$F$754=AE13))*(--ISNUMBER(FIND("-",Sheet1!$W$2:$W$754,FIND("-",Sheet1!$W$2:$W$754)+1))),Sheet1!$W$2:$W$754,""),IF(_xlpm.desc="","NOT FOUND",LEFT(_xlpm.desc,FIND("-",_xlpm.desc,FIND("-",_xlpm.desc)+1))&AE13)),LEFT(J13,FIND("-",J13,FIND("-",J13)+1))&AE13))} -> KRTS-APWN26-GETKRTSFUT6421
... A598: S0EU | B598: 5113994023 | C598: 16.04.2026 | D598: 20.07.2026 | E598: 10337044 | F598: UNITED TEXTILE MILLS PRIVATE LIMITE | G598: 1 | H598: 8909284310725 | I598: 494520815 | J598: 441811108GOLD(RP) | L598: EA | M598: 1 | N598: 231 | O598: 231 | Q598: 1563.5 | R598: 1563.5 | S598: 18058.43 | T598: 361168.5 | U598: 5 | V598: INR | X598: =IF(ISNUMBER(VALUE(LEFT(J598,1))),LEFT(J598,MIN(IFERROR(FIND("A",UPPER(J598)),LEN(J598)+1),IFERROR(FIND("B",UPPER(J598)),LEN(J598)+1),IFERROR(FIND("C",UPPER(J598)),LEN(J598)+1),IFERROR(FIND("D",UPPER(J598)),LEN(J598)+1),IFERROR(FIND("E",UPPER(J598)),LEN(J598)+1),IFERROR(FIND("F",UPPER(J598)),LEN(J598)+1),IFERROR(FIND("G",UPPER(J598)),LEN(J598)+1),IFERROR(FIND("H",UPPER(J598)),LEN(J598)+1),IFERROR(FIND("I",UPPER(J598)),LEN(J598)+1),IFERROR(FIND("J",UPPER(J598)),LEN(J598)+1),IFERROR(FIND("K",UPPER(J598)),LEN(J598)+1),IFERROR(FIND("L",UPPER(J598)),LEN(J598)+1),IFERROR(FIND("M",UPPER(J598)),LEN(J598)+1),IFERROR(FIND("N",UPPER(J598)),LEN(J598)+1),IFERROR(FIND("O",UPPER(J598)),LEN(J598)+1),IFERROR(FIND("P",UPPER(J598)),LEN(J598)+1),IFERROR(FIND("Q",UPPER(J598)),LEN(J598)+1),IFERROR(FIND("R",UPPER(J598)),LEN(J598)+1),IFERROR(FIND("S",UPPER(J598)),LEN(J598)+1),IFERROR(FIND("T",UPPER(J598)),LEN(J598)+1),IFERROR(FIND("U",UPPER(J598)),LEN(J598)+1),IFERROR(FIND("V",UPPER(J598)),LEN(J598)+1),IFERROR(FIND("W",UPPER(J598)),LEN(J598)+1),IFERROR(FIND("X",UPPER(J598)),LEN(J598)+1),IFERROR(FIND("Y",UPPER(J598)),LEN(J598)+1),IFERROR(FIND("Z",UPPER(J598)),LEN(J598)+1))-1),LEFT(TEXT(I598,"0"),LEN(TEXT(I598,"0"))-3)) -> 441811108 | Y598: =IF(ISNUMBER(SEARCH("(RP)",J598)),"RP","DC") -> RP | Z598: =IF(ISNUMBER(SEARCH("(RP)",J598)),O598,IF(RIGHT(TRIM(J598),3)=", S",O598,0)) -> 231 | AA598: =IF(ISNUMBER(SEARCH("(RP)",J598)),O598,IF(RIGHT(TRIM(J598),3)=", M",O598,0)) -> 231 | AB598: =IF(ISNUMBER(SEARCH("(RP)",J598)),O598,IF(RIGHT(TRIM(J598),3)=", L",O598,0)) -> 231 | AC598: =IF(ISNUMBER(SEARCH("(RP)",J598)),O598,IF(RIGHT(TRIM(J598),4)=", XL",O598,0)) -> 231 | AD598: =IF(ISNUMBER(SEARCH("(RP)",J598)),O598,IF(OR(RIGHT(TRIM(J598),5)=", XXL",RIGHT(TRIM(J598),5)=", 2XL"),O598,0)) -> 231 | AE598: {=IFERROR(_xlfn.XLOOKUP(H598,Sheet1!$G:$G,Sheet1!$F:$F),IFERROR(_xlfn.XLOOKUP(1,(--($X$2:$X$1074=X598))*(--ISNUMBER(MATCH($H$2:$H$1074,Sheet1!$G:$G,0))),_xlfn.XLOOKUP($H$2:$H$1074,Sheet1!$G:$G,Sheet1!$F:$F,"")),"NOT FOUND"))} -> GETKRTSFUT6210 | AF598: =IFERROR(IF(ISNUMBER(SEARCH("(RP)",J598)),TRIM(SUBSTITUTE(MID(J598,10,LEN(J598)),"(RP)","")),TRIM(MID(J598,FIND(",",J598)+1,FIND(",",J598,FIND(",",J598)+1)-FIND(",",J598)-1))),"") -> GOLD | AG598: =IF(A598="SZAF","Bangalore",IF(A598="SAEX","JHAJJAR",IF(A598="S0EU","HARIPAL",""))) -> HARIPAL | AH598: {=IF(OR(J598="",AE598="",AE598="NOT FOUND"),"",IF(Y598="RP",_xlfn.LET(_xlpm.desc,_xlfn.XLOOKUP(1,(--(Sheet1!$F$2:$F$754=AE598))*(--ISNUMBER(FIND("-",Sheet1!$W$2:$W$754,FIND("-",Sheet1!$W$2:$W$754)+1))),Sheet1!$W$2:$W$754,""),IF(_xlpm.desc="","NOT FOUND",LEFT(_xlpm.desc,FIND("-",_xlpm.desc,FIND("-",_xlpm.desc)+1))&AE598)),LEFT(J598,FIND("-",J598,FIND("-",J598)+1))&AE598))} -> KRTS-APWN26-GETKRTSFUT6210
X599: =IF(ISNUMBER(VALUE(LEFT(J599,1))),LEFT(J599,MIN(IFERROR(FIND("A",UPPER(J599)),LEN(J599)+1),IFERROR(FIND("B",UPPER(J599)),LEN(J599)+1),IFERROR(FIND("C",UPPER(J599)),LEN(J599)+1),IFERROR(FIND("D",UPPER(J599)),LEN(J599)+1),IFERROR(FIND("E",UPPER(J599)),LEN(J599)+1),IFERROR(FIND("F",UPPER(J599)),LEN(J599)+1),IFERROR(FIND("G",UPPER(J599)),LEN(J599)+1),IFERROR(FIND("H",UPPER(J599)),LEN(J599)+1),IFERROR(FIND("I",UPPER(J599)),LEN(J599)+1),IFERROR(FIND("J",UPPER(J599)),LEN(J599)+1),IFERROR(FIND("K",UPPER(J599)),LEN(J599)+1),IFERROR(FIND("L",UPPER(J599)),LEN(J599)+1),IFERROR(FIND("M",UPPER(J599)),LEN(J599)+1),IFERROR(FIND("N",UPPER(J599)),LEN(J599)+1),IFERROR(FIND("O",UPPER(J599)),LEN(J599)+1),IFERROR(FIND("P",UPPER(J599)),LEN(J599)+1),IFERROR(FIND("Q",UPPER(J599)),LEN(J599)+1),IFERROR(FIND("R",UPPER(J599)),LEN(J599)+1),IFERROR(FIND("S",UPPER(J599)),LEN(J599)+1),IFERROR(FIND("T",UPPER(J599)),LEN(J599)+1),IFERROR(FIND("U",UPPER(J599)),LEN(J599)+1),IFERROR(FIND("V",UPPER(J599)),LEN(J599)+1),IFERROR(FIND("W",UPPER(J599)),LEN(J599)+1),IFERROR(FIND("X",UPPER(J599)),LEN(J599)+1),IFERROR(FIND("Y",UPPER(J599)),LEN(J599)+1),IFERROR(FIND("Z",UPPER(J599)),LEN(J599)+1))-1),LEFT(TEXT(I599,"0"),LEN(TEXT(I599,"0"))-3)) -> #VALUE! | Y599: =IF(ISNUMBER(SEARCH("(RP)",J599)),"RP","DC") -> DC | Z599: =IF(ISNUMBER(SEARCH("(RP)",J599)),O599,IF(RIGHT(TRIM(J599),3)=", S",O599,0)) -> 0 | AA599: =IF(ISNUMBER(SEARCH("(RP)",J599)),O599,IF(RIGHT(TRIM(J599),3)=", M",O599,0)) -> 0 | AB599: =IF(ISNUMBER(SEARCH("(RP)",J599)),O599,IF(RIGHT(TRIM(J599),3)=", L",O599,0)) -> 0 | AC599: =IF(ISNUMBER(SEARCH("(RP)",J599)),O599,IF(RIGHT(TRIM(J599),4)=", XL",O599,0)) -> 0 | AD599: =IF(ISNUMBER(SEARCH("(RP)",J599)),O599,IF(OR(RIGHT(TRIM(J599),5)=", XXL",RIGHT(TRIM(J599),5)=", 2XL"),O599,0)) -> 0 | AE599: {=IFERROR(_xlfn.XLOOKUP(H599,Sheet1!$G:$G,Sheet1!$F:$F),IFERROR(_xlfn.XLOOKUP(1,(--($X$2:$X$1074=X599))*(--ISNUMBER(MATCH($H$2:$H$1074,Sheet1!$G:$G,0))),_xlfn.XLOOKUP($H$2:$H$1074,Sheet1!$G:$G,Sheet1!$F:$F,"")),"NOT FOUND"))} -> 0 | AF599: =IFERROR(IF(ISNUMBER(SEARCH("(RP)",J599)),TRIM(SUBSTITUTE(MID(J599,10,LEN(J599)),"(RP)","")),TRIM(MID(J599,FIND(",",J599)+1,FIND(",",J599,FIND(",",J599)+1)-FIND(",",J599)-1))),"") | AG599: =IF(A599="SZAF","Bangalore",IF(A599="SAEX","JHAJJAR",IF(A599="S0EU","HARIPAL",""))) | AH599: {=IF(OR(J599="",AE599="",AE599="NOT FOUND"),"",IF(Y599="RP",_xlfn.LET(_xlpm.desc,_xlfn.XLOOKUP(1,(--(Sheet1!$F$2:$F$754=AE599))*(--ISNUMBER(FIND("-",Sheet1!$W$2:$W$754,FIND("-",Sheet1!$W$2:$W$754)+1))),Sheet1!$W$2:$W$754,""),IF(_xlpm.desc="","NOT FOUND",LEFT(_xlpm.desc,FIND("-",_xlpm.desc,FIND("-",_xlpm.desc)+1))&AE599)),LEFT(J599,FIND("-",J599,FIND("-",J599)+1))&AE599))}
X600: =IF(ISNUMBER(VALUE(LEFT(J600,1))),LEFT(J600,MIN(IFERROR(FIND("A",UPPER(J600)),LEN(J600)+1),IFERROR(FIND("B",UPPER(J600)),LEN(J600)+1),IFERROR(FIND("C",UPPER(J600)),LEN(J600)+1),IFERROR(FIND("D",UPPER(J600)),LEN(J600)+1),IFERROR(FIND("E",UPPER(J600)),LEN(J600)+1),IFERROR(FIND("F",UPPER(J600)),LEN(J600)+1),IFERROR(FIND("G",UPPER(J600)),LEN(J600)+1),IFERROR(FIND("H",UPPER(J600)),LEN(J600)+1),IFERROR(FIND("I",UPPER(J600)),LEN(J600)+1),IFERROR(FIND("J",UPPER(J600)),LEN(J600)+1),IFERROR(FIND("K",UPPER(J600)),LEN(J600)+1),IFERROR(FIND("L",UPPER(J600)),LEN(J600)+1),IFERROR(FIND("M",UPPER(J600)),LEN(J600)+1),IFERROR(FIND("N",UPPER(J600)),LEN(J600)+1),IFERROR(FIND("O",UPPER(J600)),LEN(J600)+1),IFERROR(FIND("P",UPPER(J600)),LEN(J600)+1),IFERROR(FIND("Q",UPPER(J600)),LEN(J600)+1),IFERROR(FIND("R",UPPER(J600)),LEN(J600)+1),IFERROR(FIND("S",UPPER(J600)),LEN(J600)+1),IFERROR(FIND("T",UPPER(J600)),LEN(J600)+1),IFERROR(FIND("U",UPPER(J600)),LEN(J600)+1),IFERROR(FIND("V",UPPER(J600)),LEN(J600)+1),IFERROR(FIND("W",UPPER(J600)),LEN(J600)+1),IFERROR(FIND("X",UPPER(J600)),LEN(J600)+1),IFERROR(FIND("Y",UPPER(J600)),LEN(J600)+1),IFERROR(FIND("Z",UPPER(J600)),LEN(J600)+1))-1),LEFT(TEXT(I600,"0"),LEN(TEXT(I600,"0"))-3)) -> #VALUE! | Y600: =IF(ISNUMBER(SEARCH("(RP)",J600)),"RP","DC") -> DC | Z600: =IF(ISNUMBER(SEARCH("(RP)",J600)),O600,IF(RIGHT(TRIM(J600),3)=", S",O600,0)) -> 0 | AA600: =IF(ISNUMBER(SEARCH("(RP)",J600)),O600,IF(RIGHT(TRIM(J600),3)=", M",O600,0)) -> 0 | AB600: =IF(ISNUMBER(SEARCH("(RP)",J600)),O600,IF(RIGHT(TRIM(J600),3)=", L",O600,0)) -> 0 | AC600: =IF(ISNUMBER(SEARCH("(RP)",J600)),O600,IF(RIGHT(TRIM(J600),4)=", XL",O600,0)) -> 0 | AD600: =IF(ISNUMBER(SEARCH("(RP)",J600)),O600,IF(OR(RIGHT(TRIM(J600),5)=", XXL",RIGHT(TRIM(J600),5)=", 2XL"),O600,0)) -> 0 | AE600: {=IFERROR(_xlfn.XLOOKUP(H600,Sheet1!$G:$G,Sheet1!$F:$F),IFERROR(_xlfn.XLOOKUP(1,(--($X$2:$X$1074=X600))*(--ISNUMBER(MATCH($H$2:$H$1074,Sheet1!$G:$G,0))),_xlfn.XLOOKUP($H$2:$H$1074,Sheet1!$G:$G,Sheet1!$F:$F,"")),"NOT FOUND"))} -> 0 | AF600: =IFERROR(IF(ISNUMBER(SEARCH("(RP)",J600)),TRIM(SUBSTITUTE(MID(J600,10,LEN(J600)),"(RP)","")),TRIM(MID(J600,FIND(",",J600)+1,FIND(",",J600,FIND(",",J600)+1)-FIND(",",J600)-1))),"") | AG600: =IF(A600="SZAF","Bangalore",IF(A600="SAEX","JHAJJAR",IF(A600="S0EU","HARIPAL",""))) | AH600: {=IF(OR(J600="",AE600="",AE600="NOT FOUND"),"",IF(Y600="RP",_xlfn.LET(_xlpm.desc,_xlfn.XLOOKUP(1,(--(Sheet1!$F$2:$F$754=AE600))*(--ISNUMBER(FIND("-",Sheet1!$W$2:$W$754,FIND("-",Sheet1!$W$2:$W$754)+1))),Sheet1!$W$2:$W$754,""),IF(_xlpm.desc="","NOT FOUND",LEFT(_xlpm.desc,FIND("-",_xlpm.desc,FIND("-",_xlpm.desc)+1))&AE600)),LEFT(J600,FIND("-",J600,FIND("-",J600)+1))&AE600))}
X601: =IF(ISNUMBER(VALUE(LEFT(J601,1))),LEFT(J601,MIN(IFERROR(FIND("A",UPPER(J601)),LEN(J601)+1),IFERROR(FIND("B",UPPER(J601)),LEN(J601)+1),IFERROR(FIND("C",UPPER(J601)),LEN(J601)+1),IFERROR(FIND("D",UPPER(J601)),LEN(J601)+1),IFERROR(FIND("E",UPPER(J601)),LEN(J601)+1),IFERROR(FIND("F",UPPER(J601)),LEN(J601)+1),IFERROR(FIND("G",UPPER(J601)),LEN(J601)+1),IFERROR(FIND("H",UPPER(J601)),LEN(J601)+1),IFERROR(FIND("I",UPPER(J601)),LEN(J601)+1),IFERROR(FIND("J",UPPER(J601)),LEN(J601)+1),IFERROR(FIND("K",UPPER(J601)),LEN(J601)+1),IFERROR(FIND("L",UPPER(J601)),LEN(J601)+1),IFERROR(FIND("M",UPPER(J601)),LEN(J601)+1),IFERROR(FIND("N",UPPER(J601)),LEN(J601)+1),IFERROR(FIND("O",UPPER(J601)),LEN(J601)+1),IFERROR(FIND("P",UPPER(J601)),LEN(J601)+1),IFERROR(FIND("Q",UPPER(J601)),LEN(J601)+1),IFERROR(FIND("R",UPPER(J601)),LEN(J601)+1),IFERROR(FIND("S",UPPER(J601)),LEN(J601)+1),IFERROR(FIND("T",UPPER(J601)),LEN(J601)+1),IFERROR(FIND("U",UPPER(J601)),LEN(J601)+1),IFERROR(FIND("V",UPPER(J601)),LEN(J601)+1),IFERROR(FIND("W",UPPER(J601)),LEN(J601)+1),IFERROR(FIND("X",UPPER(J601)),LEN(J601)+1),IFERROR(FIND("Y",UPPER(J601)),LEN(J601)+1),IFERROR(FIND("Z",UPPER(J601)),LEN(J601)+1))-1),LEFT(TEXT(I601,"0"),LEN(TEXT(I601,"0"))-3)) -> #VALUE! | Y601: =IF(ISNUMBER(SEARCH("(RP)",J601)),"RP","DC") -> DC | Z601: =IF(ISNUMBER(SEARCH("(RP)",J601)),O601,IF(RIGHT(TRIM(J601),3)=", S",O601,0)) -> 0 | AA601: =IF(ISNUMBER(SEARCH("(RP)",J601)),O601,IF(RIGHT(TRIM(J601),3)=", M",O601,0)) -> 0 | AB601: =IF(ISNUMBER(SEARCH("(RP)",J601)),O601,IF(RIGHT(TRIM(J601),3)=", L",O601,0)) -> 0 | AC601: =IF(ISNUMBER(SEARCH("(RP)",J601)),O601,IF(RIGHT(TRIM(J601),4)=", XL",O601,0)) -> 0 | AD601: =IF(ISNUMBER(SEARCH("(RP)",J601)),O601,IF(OR(RIGHT(TRIM(J601),5)=", XXL",RIGHT(TRIM(J601),5)=", 2XL"),O601,0)) -> 0 | AE601: {=IFERROR(_xlfn.XLOOKUP(H601,Sheet1!$G:$G,Sheet1!$F:$F),IFERROR(_xlfn.XLOOKUP(1,(--($X$2:$X$1074=X601))*(--ISNUMBER(MATCH($H$2:$H$1074,Sheet1!$G:$G,0))),_xlfn.XLOOKUP($H$2:$H$1074,Sheet1!$G:$G,Sheet1!$F:$F,"")),"NOT FOUND"))} -> 0 | AF601: =IFERROR(IF(ISNUMBER(SEARCH("(RP)",J601)),TRIM(SUBSTITUTE(MID(J601,10,LEN(J601)),"(RP)","")),TRIM(MID(J601,FIND(",",J601)+1,FIND(",",J601,FIND(",",J601)+1)-FIND(",",J601)-1))),"") | AG601: =IF(A601="SZAF","Bangalore",IF(A601="SAEX","JHAJJAR",IF(A601="S0EU","HARIPAL",""))) | AH601: {=IF(OR(J601="",AE601="",AE601="NOT FOUND"),"",IF(Y601="RP",_xlfn.LET(_xlpm.desc,_xlfn.XLOOKUP(1,(--(Sheet1!$F$2:$F$754=AE601))*(--ISNUMBER(FIND("-",Sheet1!$W$2:$W$754,FIND("-",Sheet1!$W$2:$W$754)+1))),Sheet1!$W$2:$W$754,""),IF(_xlpm.desc="","NOT FOUND",LEFT(_xlpm.desc,FIND("-",_xlpm.desc,FIND("-",_xlpm.desc)+1))&AE601)),LEFT(J601,FIND("-",J601,FIND("-",J601)+1))&AE601))}
X602: =IF(ISNUMBER(VALUE(LEFT(J602,1))),LEFT(J602,MIN(IFERROR(FIND("A",UPPER(J602)),LEN(J602)+1),IFERROR(FIND("B",UPPER(J602)),LEN(J602)+1),IFERROR(FIND("C",UPPER(J602)),LEN(J602)+1),IFERROR(FIND("D",UPPER(J602)),LEN(J602)+1),IFERROR(FIND("E",UPPER(J602)),LEN(J602)+1),IFERROR(FIND("F",UPPER(J602)),LEN(J602)+1),IFERROR(FIND("G",UPPER(J602)),LEN(J602)+1),IFERROR(FIND("H",UPPER(J602)),LEN(J602)+1),IFERROR(FIND("I",UPPER(J602)),LEN(J602)+1),IFERROR(FIND("J",UPPER(J602)),LEN(J602)+1),IFERROR(FIND("K",UPPER(J602)),LEN(J602)+1),IFERROR(FIND("L",UPPER(J602)),LEN(J602)+1),IFERROR(FIND("M",UPPER(J602)),LEN(J602)+1),IFERROR(FIND("N",UPPER(J602)),LEN(J602)+1),IFERROR(FIND("O",UPPER(J602)),LEN(J602)+1),IFERROR(FIND("P",UPPER(J602)),LEN(J602)+1),IFERROR(FIND("Q",UPPER(J602)),LEN(J602)+1),IFERROR(FIND("R",UPPER(J602)),LEN(J602)+1),IFERROR(FIND("S",UPPER(J602)),LEN(J602)+1),IFERROR(FIND("T",UPPER(J602)),LEN(J602)+1),IFERROR(FIND("U",UPPER(J602)),LEN(J602)+1),IFERROR(FIND("V",UPPER(J602)),LEN(J602)+1),IFERROR(FIND("W",UPPER(J602)),LEN(J602)+1),IFERROR(FIND("X",UPPER(J602)),LEN(J602)+1),IFERROR(FIND("Y",UPPER(J602)),LEN(J602)+1),IFERROR(FIND("Z",UPPER(J602)),LEN(J602)+1))-1),LEFT(TEXT(I602,"0"),LEN(TEXT(I602,"0"))-3)) -> #VALUE! | Y602: =IF(ISNUMBER(SEARCH("(RP)",J602)),"RP","DC") -> DC | Z602: =IF(ISNUMBER(SEARCH("(RP)",J602)),O602,IF(RIGHT(TRIM(J602),3)=", S",O602,0)) -> 0 | AA602: =IF(ISNUMBER(SEARCH("(RP)",J602)),O602,IF(RIGHT(TRIM(J602),3)=", M",O602,0)) -> 0 | AB602: =IF(ISNUMBER(SEARCH("(RP)",J602)),O602,IF(RIGHT(TRIM(J602),3)=", L",O602,0)) -> 0 | AC602: =IF(ISNUMBER(SEARCH("(RP)",J602)),O602,IF(RIGHT(TRIM(J602),4)=", XL",O602,0)) -> 0 | AD602: =IF(ISNUMBER(SEARCH("(RP)",J602)),O602,IF(OR(RIGHT(TRIM(J602),5)=", XXL",RIGHT(TRIM(J602),5)=", 2XL"),O602,0)) -> 0 | AE602: {=IFERROR(_xlfn.XLOOKUP(H602,Sheet1!$G:$G,Sheet1!$F:$F),IFERROR(_xlfn.XLOOKUP(1,(--($X$2:$X$1074=X602))*(--ISNUMBER(MATCH($H$2:$H$1074,Sheet1!$G:$G,0))),_xlfn.XLOOKUP($H$2:$H$1074,Sheet1!$G:$G,Sheet1!$F:$F,"")),"NOT FOUND"))} -> 0 | AF602: =IFERROR(IF(ISNUMBER(SEARCH("(RP)",J602)),TRIM(SUBSTITUTE(MID(J602,10,LEN(J602)),"(RP)","")),TRIM(MID(J602,FIND(",",J602)+1,FIND(",",J602,FIND(",",J602)+1)-FIND(",",J602)-1))),"") | AG602: =IF(A602="SZAF","Bangalore",IF(A602="SAEX","JHAJJAR",IF(A602="S0EU","HARIPAL",""))) | AH602: {=IF(OR(J602="",AE602="",AE602="NOT FOUND"),"",IF(Y602="RP",_xlfn.LET(_xlpm.desc,_xlfn.XLOOKUP(1,(--(Sheet1!$F$2:$F$754=AE602))*(--ISNUMBER(FIND("-",Sheet1!$W$2:$W$754,FIND("-",Sheet1!$W$2:$W$754)+1))),Sheet1!$W$2:$W$754,""),IF(_xlpm.desc="","NOT FOUND",LEFT(_xlpm.desc,FIND("-",_xlpm.desc,FIND("-",_xlpm.desc)+1))&AE602)),LEFT(J602,FIND("-",J602,FIND("-",J602)+1))&AE602))}
X603: =IF(ISNUMBER(VALUE(LEFT(J603,1))),LEFT(J603,MIN(IFERROR(FIND("A",UPPER(J603)),LEN(J603)+1),IFERROR(FIND("B",UPPER(J603)),LEN(J603)+1),IFERROR(FIND("C",UPPER(J603)),LEN(J603)+1),IFERROR(FIND("D",UPPER(J603)),LEN(J603)+1),IFERROR(FIND("E",UPPER(J603)),LEN(J603)+1),IFERROR(FIND("F",UPPER(J603)),LEN(J603)+1),IFERROR(FIND("G",UPPER(J603)),LEN(J603)+1),IFERROR(FIND("H",UPPER(J603)),LEN(J603)+1),IFERROR(FIND("I",UPPER(J603)),LEN(J603)+1),IFERROR(FIND("J",UPPER(J603)),LEN(J603)+1),IFERROR(FIND("K",UPPER(J603)),LEN(J603)+1),IFERROR(FIND("L",UPPER(J603)),LEN(J603)+1),IFERROR(FIND("M",UPPER(J603)),LEN(J603)+1),IFERROR(FIND("N",UPPER(J603)),LEN(J603)+1),IFERROR(FIND("O",UPPER(J603)),LEN(J603)+1),IFERROR(FIND("P",UPPER(J603)),LEN(J603)+1),IFERROR(FIND("Q",UPPER(J603)),LEN(J603)+1),IFERROR(FIND("R",UPPER(J603)),LEN(J603)+1),IFERROR(FIND("S",UPPER(J603)),LEN(J603)+1),IFERROR(FIND("T",UPPER(J603)),LEN(J603)+1),IFERROR(FIND("U",UPPER(J603)),LEN(J603)+1),IFERROR(FIND("V",UPPER(J603)),LEN(J603)+1),IFERROR(FIND("W",UPPER(J603)),LEN(J603)+1),IFERROR(FIND("X",UPPER(J603)),LEN(J603)+1),IFERROR(FIND("Y",UPPER(J603)),LEN(J603)+1),IFERROR(FIND("Z",UPPER(J603)),LEN(J603)+1))-1),LEFT(TEXT(I603,"0"),LEN(TEXT(I603,"0"))-3)) -> #VALUE! | Y603: =IF(ISNUMBER(SEARCH("(RP)",J603)),"RP","DC") -> DC | Z603: =IF(ISNUMBER(SEARCH("(RP)",J603)),O603,IF(RIGHT(TRIM(J603),3)=", S",O603,0)) -> 0 | AA603: =IF(ISNUMBER(SEARCH("(RP)",J603)),O603,IF(RIGHT(TRIM(J603),3)=", M",O603,0)) -> 0 | AB603: =IF(ISNUMBER(SEARCH("(RP)",J603)),O603,IF(RIGHT(TRIM(J603),3)=", L",O603,0)) -> 0 | AC603: =IF(ISNUMBER(SEARCH("(RP)",J603)),O603,IF(RIGHT(TRIM(J603),4)=", XL",O603,0)) -> 0 | AD603: =IF(ISNUMBER(SEARCH("(RP)",J603)),O603,IF(OR(RIGHT(TRIM(J603),5)=", XXL",RIGHT(TRIM(J603),5)=", 2XL"),O603,0)) -> 0 | AE603: {=IFERROR(_xlfn.XLOOKUP(H603,Sheet1!$G:$G,Sheet1!$F:$F),IFERROR(_xlfn.XLOOKUP(1,(--($X$2:$X$1074=X603))*(--ISNUMBER(MATCH($H$2:$H$1074,Sheet1!$G:$G,0))),_xlfn.XLOOKUP($H$2:$H$1074,Sheet1!$G:$G,Sheet1!$F:$F,"")),"NOT FOUND"))} -> 0 | AF603: =IFERROR(IF(ISNUMBER(SEARCH("(RP)",J603)),TRIM(SUBSTITUTE(MID(J603,10,LEN(J603)),"(RP)","")),TRIM(MID(J603,FIND(",",J603)+1,FIND(",",J603,FIND(",",J603)+1)-FIND(",",J603)-1))),"") | AG603: =IF(A603="SZAF","Bangalore",IF(A603="SAEX","JHAJJAR",IF(A603="S0EU","HARIPAL",""))) | AH603: {=IF(OR(J603="",AE603="",AE603="NOT FOUND"),"",IF(Y603="RP",_xlfn.LET(_xlpm.desc,_xlfn.XLOOKUP(1,(--(Sheet1!$F$2:$F$754=AE603))*(--ISNUMBER(FIND("-",Sheet1!$W$2:$W$754,FIND("-",Sheet1!$W$2:$W$754)+1))),Sheet1!$W$2:$W$754,""),IF(_xlpm.desc="","NOT FOUND",LEFT(_xlpm.desc,FIND("-",_xlpm.desc,FIND("-",_xlpm.desc)+1))&AE603)),LEFT(J603,FIND("-",J603,FIND("-",J603)+1))&AE603))}
X604: =IF(ISNUMBER(VALUE(LEFT(J604,1))),LEFT(J604,MIN(IFERROR(FIND("A",UPPER(J604)),LEN(J604)+1),IFERROR(FIND("B",UPPER(J604)),LEN(J604)+1),IFERROR(FIND("C",UPPER(J604)),LEN(J604)+1),IFERROR(FIND("D",UPPER(J604)),LEN(J604)+1),IFERROR(FIND("E",UPPER(J604)),LEN(J604)+1),IFERROR(FIND("F",UPPER(J604)),LEN(J604)+1),IFERROR(FIND("G",UPPER(J604)),LEN(J604)+1),IFERROR(FIND("H",UPPER(J604)),LEN(J604)+1),IFERROR(FIND("I",UPPER(J604)),LEN(J604)+1),IFERROR(FIND("J",UPPER(J604)),LEN(J604)+1),IFERROR(FIND("K",UPPER(J604)),LEN(J604)+1),IFERROR(FIND("L",UPPER(J604)),LEN(J604)+1),IFERROR(FIND("M",UPPER(J604)),LEN(J604)+1),IFERROR(FIND("N",UPPER(J604)),LEN(J604)+1),IFERROR(FIND("O",UPPER(J604)),LEN(J604)+1),IFERROR(FIND("P",UPPER(J604)),LEN(J604)+1),IFERROR(FIND("Q",UPPER(J604)),LEN(J604)+1),IFERROR(FIND("R",UPPER(J604)),LEN(J604)+1),IFERROR(FIND("S",UPPER(J604)),LEN(J604)+1),IFERROR(FIND("T",UPPER(J604)),LEN(J604)+1),IFERROR(FIND("U",UPPER(J604)),LEN(J604)+1),IFERROR(FIND("V",UPPER(J604)),LEN(J604)+1),IFERROR(FIND("W",UPPER(J604)),LEN(J604)+1),IFERROR(FIND("X",UPPER(J604)),LEN(J604)+1),IFERROR(FIND("Y",UPPER(J604)),LEN(J604)+1),IFERROR(FIND("Z",UPPER(J604)),LEN(J604)+1))-1),LEFT(TEXT(I604,"0"),LEN(TEXT(I604,"0"))-3)) -> #VALUE! | Y604: =IF(ISNUMBER(SEARCH("(RP)",J604)),"RP","DC") -> DC | Z604: =IF(ISNUMBER(SEARCH("(RP)",J604)),O604,IF(RIGHT(TRIM(J604),3)=", S",O604,0)) -> 0 | AA604: =IF(ISNUMBER(SEARCH("(RP)",J604)),O604,IF(RIGHT(TRIM(J604),3)=", M",O604,0)) -> 0 | AB604: =IF(ISNUMBER(SEARCH("(RP)",J604)),O604,IF(RIGHT(TRIM(J604),3)=", L",O604,0)) -> 0 | AC604: =IF(ISNUMBER(SEARCH("(RP)",J604)),O604,IF(RIGHT(TRIM(J604),4)=", XL",O604,0)) -> 0 | AD604: =IF(ISNUMBER(SEARCH("(RP)",J604)),O604,IF(OR(RIGHT(TRIM(J604),5)=", XXL",RIGHT(TRIM(J604),5)=", 2XL"),O604,0)) -> 0 | AE604: {=IFERROR(_xlfn.XLOOKUP(H604,Sheet1!$G:$G,Sheet1!$F:$F),IFERROR(_xlfn.XLOOKUP(1,(--($X$2:$X$1074=X604))*(--ISNUMBER(MATCH($H$2:$H$1074,Sheet1!$G:$G,0))),_xlfn.XLOOKUP($H$2:$H$1074,Sheet1!$G:$G,Sheet1!$F:$F,"")),"NOT FOUND"))} -> 0 | AF604: =IFERROR(IF(ISNUMBER(SEARCH("(RP)",J604)),TRIM(SUBSTITUTE(MID(J604,10,LEN(J604)),"(RP)","")),TRIM(MID(J604,FIND(",",J604)+1,FIND(",",J604,FIND(",",J604)+1)-FIND(",",J604)-1))),"") | AG604: =IF(A604="SZAF","Bangalore",IF(A604="SAEX","JHAJJAR",IF(A604="S0EU","HARIPAL",""))) | AH604: {=IF(OR(J604="",AE604="",AE604="NOT FOUND"),"",IF(Y604="RP",_xlfn.LET(_xlpm.desc,_xlfn.XLOOKUP(1,(--(Sheet1!$F$2:$F$754=AE604))*(--ISNUMBER(FIND("-",Sheet1!$W$2:$W$754,FIND("-",Sheet1!$W$2:$W$754)+1))),Sheet1!$W$2:$W$754,""),IF(_xlpm.desc="","NOT FOUND",LEFT(_xlpm.desc,FIND("-",_xlpm.desc,FIND("-",_xlpm.desc)+1))&AE604)),LEFT(J604,FIND("-",J604,FIND("-",J604)+1))&AE604))}
X605: =IF(ISNUMBER(VALUE(LEFT(J605,1))),LEFT(J605,MIN(IFERROR(FIND("A",UPPER(J605)),LEN(J605)+1),IFERROR(FIND("B",UPPER(J605)),LEN(J605)+1),IFERROR(FIND("C",UPPER(J605)),LEN(J605)+1),IFERROR(FIND("D",UPPER(J605)),LEN(J605)+1),IFERROR(FIND("E",UPPER(J605)),LEN(J605)+1),IFERROR(FIND("F",UPPER(J605)),LEN(J605)+1),IFERROR(FIND("G",UPPER(J605)),LEN(J605)+1),IFERROR(FIND("H",UPPER(J605)),LEN(J605)+1),IFERROR(FIND("I",UPPER(J605)),LEN(J605)+1),IFERROR(FIND("J",UPPER(J605)),LEN(J605)+1),IFERROR(FIND("K",UPPER(J605)),LEN(J605)+1),IFERROR(FIND("L",UPPER(J605)),LEN(J605)+1),IFERROR(FIND("M",UPPER(J605)),LEN(J605)+1),IFERROR(FIND("N",UPPER(J605)),LEN(J605)+1),IFERROR(FIND("O",UPPER(J605)),LEN(J605)+1),IFERROR(FIND("P",UPPER(J605)),LEN(J605)+1),IFERROR(FIND("Q",UPPER(J605)),LEN(J605)+1),IFERROR(FIND("R",UPPER(J605)),LEN(J605)+1),IFERROR(FIND("S",UPPER(J605)),LEN(J605)+1),IFERROR(FIND("T",UPPER(J605)),LEN(J605)+1),IFERROR(FIND("U",UPPER(J605)),LEN(J605)+1),IFERROR(FIND("V",UPPER(J605)),LEN(J605)+1),IFERROR(FIND("W",UPPER(J605)),LEN(J605)+1),IFERROR(FIND("X",UPPER(J605)),LEN(J605)+1),IFERROR(FIND("Y",UPPER(J605)),LEN(J605)+1),IFERROR(FIND("Z",UPPER(J605)),LEN(J605)+1))-1),LEFT(TEXT(I605,"0"),LEN(TEXT(I605,"0"))-3)) -> #VALUE! | Y605: =IF(ISNUMBER(SEARCH("(RP)",J605)),"RP","DC") -> DC | Z605: =IF(ISNUMBER(SEARCH("(RP)",J605)),O605,IF(RIGHT(TRIM(J605),3)=", S",O605,0)) -> 0 | AA605: =IF(ISNUMBER(SEARCH("(RP)",J605)),O605,IF(RIGHT(TRIM(J605),3)=", M",O605,0)) -> 0 | AB605: =IF(ISNUMBER(SEARCH("(RP)",J605)),O605,IF(RIGHT(TRIM(J605),3)=", L",O605,0)) -> 0 | AC605: =IF(ISNUMBER(SEARCH("(RP)",J605)),O605,IF(RIGHT(TRIM(J605),4)=", XL",O605,0)) -> 0 | AD605: =IF(ISNUMBER(SEARCH("(RP)",J605)),O605,IF(OR(RIGHT(TRIM(J605),5)=", XXL",RIGHT(TRIM(J605),5)=", 2XL"),O605,0)) -> 0 | AE605: {=IFERROR(_xlfn.XLOOKUP(H605,Sheet1!$G:$G,Sheet1!$F:$F),IFERROR(_xlfn.XLOOKUP(1,(--($X$2:$X$1074=X605))*(--ISNUMBER(MATCH($H$2:$H$1074,Sheet1!$G:$G,0))),_xlfn.XLOOKUP($H$2:$H$1074,Sheet1!$G:$G,Sheet1!$F:$F,"")),"NOT FOUND"))} -> 0 | AF605: =IFERROR(IF(ISNUMBER(SEARCH("(RP)",J605)),TRIM(SUBSTITUTE(MID(J605,10,LEN(J605)),"(RP)","")),TRIM(MID(J605,FIND(",",J605)+1,FIND(",",J605,FIND(",",J605)+1)-FIND(",",J605)-1))),"") | AG605: =IF(A605="SZAF","Bangalore",IF(A605="SAEX","JHAJJAR",IF(A605="S0EU","HARIPAL",""))) | AH605: {=IF(OR(J605="",AE605="",AE605="NOT FOUND"),"",IF(Y605="RP",_xlfn.LET(_xlpm.desc,_xlfn.XLOOKUP(1,(--(Sheet1!$F$2:$F$754=AE605))*(--ISNUMBER(FIND("-",Sheet1!$W$2:$W$754,FIND("-",Sheet1!$W$2:$W$754)+1))),Sheet1!$W$2:$W$754,""),IF(_xlpm.desc="","NOT FOUND",LEFT(_xlpm.desc,FIND("-",_xlpm.desc,FIND("-",_xlpm.desc)+1))&AE605)),LEFT(J605,FIND("-",J605,FIND("-",J605)+1))&AE605))}
